2025-08-08 21:49:56,948 - scribsy - ERROR - logging:68 - Error in Unhandled exception at: /patients/: (sqlite3.IntegrityError) NOT NULL constraint failed: patients.id
[SQL: INSERT INTO patients (user_id, first_name, last_name, date_of_birth, phone_number, email, address, city, state, zip_code, created_at, updated_at) VALUES (?, ?, ?, ?, ?, ?, ?, ?, ?, ?, ?, ?)]
[parameters: (10, 'John', 'Doe', '1980-01-15', '(555) 123-4567', 'john.doe@example.com', '123 Main St', None, None, None, '2025-08-09 02:49:56.947248', '2025-08-09 02:49:56.947252')]
(Background on this error at: https://sqlalche.me/e/20/gkpj) - anonymous
Traceback (most recent call last):
  File "C:\Users\zelun\AppData\Roaming\Python\Python313\site-packages\sqlalchemy\engine\base.py", line 1961, in _exec_single_context
    self.dialect.do_execute(
    ~~~~~~~~~~~~~~~~~~~~~~~^
        cursor, str_statement, effective_parameters, context
        ^^^^^^^^^^^^^^^^^^^^^^^^^^^^^^^^^^^^^^^^^^^^^^^^^^^^
    )
    ^
  File "C:\Users\zelun\AppData\Roaming\Python\Python313\site-packages\sqlalchemy\engine\default.py", line 944, in do_execute
    cursor.execute(statement, parameters)
    ~~~~~~~~~~~~~~^^^^^^^^^^^^^^^^^^^^^^^
sqlite3.IntegrityError: NOT NULL constraint failed: patients.id

The above exception was the direct cause of the following exception:

Traceback (most recent call last):
  File "C:\Users\zelun\AppData\Roaming\Python\Python313\site-packages\starlette\middleware\errors.py", line 165, in __call__
    await self.app(scope, receive, _send)
  File "C:\Users\zelun\AppData\Roaming\Python\Python313\site-packages\starlette\middleware\cors.py", line 85, in __call__
    await self.app(scope, receive, send)
  File "C:\Users\zelun\AppData\Roaming\Python\Python313\site-packages\starlette\middleware\exceptions.py", line 62, in __call__
    await wrap_app_handling_exceptions(self.app, conn)(scope, receive, send)
  File "C:\Users\zelun\AppData\Roaming\Python\Python313\site-packages\starlette\_exception_handler.py", line 53, in wrapped_app
    raise exc
  File "C:\Users\zelun\AppData\Roaming\Python\Python313\site-packages\starlette\_exception_handler.py", line 42, in wrapped_app
    await app(scope, receive, sender)
  File "C:\Users\zelun\AppData\Roaming\Python\Python313\site-packages\starlette\routing.py", line 714, in __call__
    await self.middleware_stack(scope, receive, send)
  File "C:\Users\zelun\AppData\Roaming\Python\Python313\site-packages\starlette\routing.py", line 734, in app
    await route.handle(scope, receive, send)
  File "C:\Users\zelun\AppData\Roaming\Python\Python313\site-packages\starlette\routing.py", line 288, in handle
    await self.app(scope, receive, send)
  File "C:\Users\zelun\AppData\Roaming\Python\Python313\site-packages\starlette\routing.py", line 76, in app
    await wrap_app_handling_exceptions(app, request)(scope, receive, send)
  File "C:\Users\zelun\AppData\Roaming\Python\Python313\site-packages\starlette\_exception_handler.py", line 53, in wrapped_app
    raise exc
  File "C:\Users\zelun\AppData\Roaming\Python\Python313\site-packages\starlette\_exception_handler.py", line 42, in wrapped_app
    await app(scope, receive, sender)
  File "C:\Users\zelun\AppData\Roaming\Python\Python313\site-packages\starlette\routing.py", line 73, in app
    response = await f(request)
               ^^^^^^^^^^^^^^^^
  File "C:\Users\zelun\AppData\Roaming\Python\Python313\site-packages\fastapi\routing.py", line 301, in app
    raw_response = await run_endpoint_function(
                   ^^^^^^^^^^^^^^^^^^^^^^^^^^^^
    ...<3 lines>...
    )
    ^
  File "C:\Users\zelun\AppData\Roaming\Python\Python313\site-packages\fastapi\routing.py", line 214, in run_endpoint_function
    return await run_in_threadpool(dependant.call, **values)
           ^^^^^^^^^^^^^^^^^^^^^^^^^^^^^^^^^^^^^^^^^^^^^^^^^
  File "C:\Users\zelun\AppData\Roaming\Python\Python313\site-packages\starlette\concurrency.py", line 37, in run_in_threadpool
    return await anyio.to_thread.run_sync(func)
           ^^^^^^^^^^^^^^^^^^^^^^^^^^^^^^^^^^^^
  File "C:\Users\zelun\AppData\Roaming\Python\Python313\site-packages\anyio\to_thread.py", line 56, in run_sync
    return await get_async_backend().run_sync_in_worker_thread(
           ^^^^^^^^^^^^^^^^^^^^^^^^^^^^^^^^^^^^^^^^^^^^^^^^^^^^
        func, args, abandon_on_cancel=abandon_on_cancel, limiter=limiter
        ^^^^^^^^^^^^^^^^^^^^^^^^^^^^^^^^^^^^^^^^^^^^^^^^^^^^^^^^^^^^^^^^
    )
    ^
  File "C:\Users\zelun\AppData\Roaming\Python\Python313\site-packages\anyio\_backends\_asyncio.py", line 2470, in run_sync_in_worker_thread
    return await future
           ^^^^^^^^^^^^
  File "C:\Users\zelun\AppData\Roaming\Python\Python313\site-packages\anyio\_backends\_asyncio.py", line 967, in run
    result = context.run(func, *args)
  File "C:\Users\zelun\Desktop\Projects\Scribsy\app\api\endpoints\patients.py", line 69, in create_patient
    return crud_patients.create_patient(db, schemas.PatientCreate(**patient_data))
           ~~~~~~~~~~~~~~~~~~~~~~~~~~~~^^^^^^^^^^^^^^^^^^^^^^^^^^^^^^^^^^^^^^^^^^^
  File "C:\Users\zelun\Desktop\Projects\Scribsy\app\crud\patients.py", line 15, in create_patient
    db.commit()
    ~~~~~~~~~^^
  File "C:\Users\zelun\AppData\Roaming\Python\Python313\site-packages\sqlalchemy\orm\session.py", line 2032, in commit
    trans.commit(_to_root=True)
    ~~~~~~~~~~~~^^^^^^^^^^^^^^^
  File "<string>", line 2, in commit
  File "C:\Users\zelun\AppData\Roaming\Python\Python313\site-packages\sqlalchemy\orm\state_changes.py", line 137, in _go
    ret_value = fn(self, *arg, **kw)
  File "C:\Users\zelun\AppData\Roaming\Python\Python313\site-packages\sqlalchemy\orm\session.py", line 1313, in commit
    self._prepare_impl()
    ~~~~~~~~~~~~~~~~~~^^
  File "<string>", line 2, in _prepare_impl
  File "C:\Users\zelun\AppData\Roaming\Python\Python313\site-packages\sqlalchemy\orm\state_changes.py", line 137, in _go
    ret_value = fn(self, *arg, **kw)
  File "C:\Users\zelun\AppData\Roaming\Python\Python313\site-packages\sqlalchemy\orm\session.py", line 1288, in _prepare_impl
    self.session.flush()
    ~~~~~~~~~~~~~~~~~~^^
  File "C:\Users\zelun\AppData\Roaming\Python\Python313\site-packages\sqlalchemy\orm\session.py", line 4345, in flush
    self._flush(objects)
    ~~~~~~~~~~~^^^^^^^^^
  File "C:\Users\zelun\AppData\Roaming\Python\Python313\site-packages\sqlalchemy\orm\session.py", line 4480, in _flush
    with util.safe_reraise():
         ~~~~~~~~~~~~~~~~~^^
  File "C:\Users\zelun\AppData\Roaming\Python\Python313\site-packages\sqlalchemy\util\langhelpers.py", line 224, in __exit__
    raise exc_value.with_traceback(exc_tb)
  File "C:\Users\zelun\AppData\Roaming\Python\Python313\site-packages\sqlalchemy\orm\session.py", line 4441, in _flush
    flush_context.execute()
    ~~~~~~~~~~~~~~~~~~~~~^^
  File "C:\Users\zelun\AppData\Roaming\Python\Python313\site-packages\sqlalchemy\orm\unitofwork.py", line 466, in execute
    rec.execute(self)
    ~~~~~~~~~~~^^^^^^
  File "C:\Users\zelun\AppData\Roaming\Python\Python313\site-packages\sqlalchemy\orm\unitofwork.py", line 642, in execute
    util.preloaded.orm_persistence.save_obj(
    ~~~~~~~~~~~~~~~~~~~~~~~~~~~~~~~~~~~~~~~^
        self.mapper,
        ^^^^^^^^^^^^
        uow.states_for_mapper_hierarchy(self.mapper, False, False),
        ^^^^^^^^^^^^^^^^^^^^^^^^^^^^^^^^^^^^^^^^^^^^^^^^^^^^^^^^^^^
        uow,
        ^^^^
    )
    ^
  File "C:\Users\zelun\AppData\Roaming\Python\Python313\site-packages\sqlalchemy\orm\persistence.py", line 93, in save_obj
    _emit_insert_statements(
    ~~~~~~~~~~~~~~~~~~~~~~~^
        base_mapper,
        ^^^^^^^^^^^^
    ...<3 lines>...
        insert,
        ^^^^^^^
    )
    ^
  File "C:\Users\zelun\AppData\Roaming\Python\Python313\site-packages\sqlalchemy\orm\persistence.py", line 1233, in _emit_insert_statements
    result = connection.execute(
        statement,
        params,
        execution_options=execution_options,
    )
  File "C:\Users\zelun\AppData\Roaming\Python\Python313\site-packages\sqlalchemy\engine\base.py", line 1413, in execute
    return meth(
        self,
        distilled_parameters,
        execution_options or NO_OPTIONS,
    )
  File "C:\Users\zelun\AppData\Roaming\Python\Python313\site-packages\sqlalchemy\sql\elements.py", line 526, in _execute_on_connection
    return connection._execute_clauseelement(
           ~~~~~~~~~~~~~~~~~~~~~~~~~~~~~~~~~^
        self, distilled_params, execution_options
        ^^^^^^^^^^^^^^^^^^^^^^^^^^^^^^^^^^^^^^^^^
    )
    ^
  File "C:\Users\zelun\AppData\Roaming\Python\Python313\site-packages\sqlalchemy\engine\base.py", line 1635, in _execute_clauseelement
    ret = self._execute_context(
        dialect,
    ...<8 lines>...
        cache_hit=cache_hit,
    )
  File "C:\Users\zelun\AppData\Roaming\Python\Python313\site-packages\sqlalchemy\engine\base.py", line 1840, in _execute_context
    return self._exec_single_context(
           ~~~~~~~~~~~~~~~~~~~~~~~~~^
        dialect, context, statement, parameters
        ^^^^^^^^^^^^^^^^^^^^^^^^^^^^^^^^^^^^^^^
    )
    ^
  File "C:\Users\zelun\AppData\Roaming\Python\Python313\site-packages\sqlalchemy\engine\base.py", line 1980, in _exec_single_context
    self._handle_dbapi_exception(
    ~~~~~~~~~~~~~~~~~~~~~~~~~~~~^
        e, str_statement, effective_parameters, cursor, context
        ^^^^^^^^^^^^^^^^^^^^^^^^^^^^^^^^^^^^^^^^^^^^^^^^^^^^^^^
    )
    ^
  File "C:\Users\zelun\AppData\Roaming\Python\Python313\site-packages\sqlalchemy\engine\base.py", line 2349, in _handle_dbapi_exception
    raise sqlalchemy_exception.with_traceback(exc_info[2]) from e
  File "C:\Users\zelun\AppData\Roaming\Python\Python313\site-packages\sqlalchemy\engine\base.py", line 1961, in _exec_single_context
    self.dialect.do_execute(
    ~~~~~~~~~~~~~~~~~~~~~~~^
        cursor, str_statement, effective_parameters, context
        ^^^^^^^^^^^^^^^^^^^^^^^^^^^^^^^^^^^^^^^^^^^^^^^^^^^^
    )
    ^
  File "C:\Users\zelun\AppData\Roaming\Python\Python313\site-packages\sqlalchemy\engine\default.py", line 944, in do_execute
    cursor.execute(statement, parameters)
    ~~~~~~~~~~~~~~^^^^^^^^^^^^^^^^^^^^^^^
sqlalchemy.exc.IntegrityError: (sqlite3.IntegrityError) NOT NULL constraint failed: patients.id
[SQL: INSERT INTO patients (user_id, first_name, last_name, date_of_birth, phone_number, email, address, city, state, zip_code, created_at, updated_at) VALUES (?, ?, ?, ?, ?, ?, ?, ?, ?, ?, ?, ?)]
[parameters: (10, 'John', 'Doe', '1980-01-15', '(555) 123-4567', 'john.doe@example.com', '123 Main St', None, None, None, '2025-08-09 02:49:56.947248', '2025-08-09 02:49:56.947252')]
(Background on this error at: https://sqlalche.me/e/20/gkpj)
2025-08-08 21:52:17,551 - scribsy - ERROR - logging:68 - Error in Unhandled exception at: /patients/: (sqlite3.IntegrityError) NOT NULL constraint failed: patients.id
[SQL: INSERT INTO patients (user_id, first_name, last_name, date_of_birth, phone_number, email, address, city, state, zip_code, created_at, updated_at) VALUES (?, ?, ?, ?, ?, ?, ?, ?, ?, ?, ?, ?)]
[parameters: (8, 'Zelun', 'He', '1999-10-20', '314-526-1141', 'zelunhe@gmail.com', '5183 MILD DR', None, None, None, '2025-08-09 02:52:17.550704', '2025-08-09 02:52:17.550708')]
(Background on this error at: https://sqlalche.me/e/20/gkpj) - anonymous
Traceback (most recent call last):
  File "C:\Users\zelun\AppData\Roaming\Python\Python313\site-packages\sqlalchemy\engine\base.py", line 1961, in _exec_single_context
    self.dialect.do_execute(
    ~~~~~~~~~~~~~~~~~~~~~~~^
        cursor, str_statement, effective_parameters, context
        ^^^^^^^^^^^^^^^^^^^^^^^^^^^^^^^^^^^^^^^^^^^^^^^^^^^^
    )
    ^
  File "C:\Users\zelun\AppData\Roaming\Python\Python313\site-packages\sqlalchemy\engine\default.py", line 944, in do_execute
    cursor.execute(statement, parameters)
    ~~~~~~~~~~~~~~^^^^^^^^^^^^^^^^^^^^^^^
sqlite3.IntegrityError: NOT NULL constraint failed: patients.id

The above exception was the direct cause of the following exception:

Traceback (most recent call last):
  File "C:\Users\zelun\AppData\Roaming\Python\Python313\site-packages\starlette\middleware\errors.py", line 165, in __call__
    await self.app(scope, receive, _send)
  File "C:\Users\zelun\AppData\Roaming\Python\Python313\site-packages\starlette\middleware\cors.py", line 93, in __call__
    await self.simple_response(scope, receive, send, request_headers=headers)
  File "C:\Users\zelun\AppData\Roaming\Python\Python313\site-packages\starlette\middleware\cors.py", line 144, in simple_response
    await self.app(scope, receive, send)
  File "C:\Users\zelun\AppData\Roaming\Python\Python313\site-packages\starlette\middleware\exceptions.py", line 62, in __call__
    await wrap_app_handling_exceptions(self.app, conn)(scope, receive, send)
  File "C:\Users\zelun\AppData\Roaming\Python\Python313\site-packages\starlette\_exception_handler.py", line 53, in wrapped_app
    raise exc
  File "C:\Users\zelun\AppData\Roaming\Python\Python313\site-packages\starlette\_exception_handler.py", line 42, in wrapped_app
    await app(scope, receive, sender)
  File "C:\Users\zelun\AppData\Roaming\Python\Python313\site-packages\starlette\routing.py", line 714, in __call__
    await self.middleware_stack(scope, receive, send)
  File "C:\Users\zelun\AppData\Roaming\Python\Python313\site-packages\starlette\routing.py", line 734, in app
    await route.handle(scope, receive, send)
  File "C:\Users\zelun\AppData\Roaming\Python\Python313\site-packages\starlette\routing.py", line 288, in handle
    await self.app(scope, receive, send)
  File "C:\Users\zelun\AppData\Roaming\Python\Python313\site-packages\starlette\routing.py", line 76, in app
    await wrap_app_handling_exceptions(app, request)(scope, receive, send)
  File "C:\Users\zelun\AppData\Roaming\Python\Python313\site-packages\starlette\_exception_handler.py", line 53, in wrapped_app
    raise exc
  File "C:\Users\zelun\AppData\Roaming\Python\Python313\site-packages\starlette\_exception_handler.py", line 42, in wrapped_app
    await app(scope, receive, sender)
  File "C:\Users\zelun\AppData\Roaming\Python\Python313\site-packages\starlette\routing.py", line 73, in app
    response = await f(request)
               ^^^^^^^^^^^^^^^^
  File "C:\Users\zelun\AppData\Roaming\Python\Python313\site-packages\fastapi\routing.py", line 301, in app
    raw_response = await run_endpoint_function(
                   ^^^^^^^^^^^^^^^^^^^^^^^^^^^^
    ...<3 lines>...
    )
    ^
  File "C:\Users\zelun\AppData\Roaming\Python\Python313\site-packages\fastapi\routing.py", line 214, in run_endpoint_function
    return await run_in_threadpool(dependant.call, **values)
           ^^^^^^^^^^^^^^^^^^^^^^^^^^^^^^^^^^^^^^^^^^^^^^^^^
  File "C:\Users\zelun\AppData\Roaming\Python\Python313\site-packages\starlette\concurrency.py", line 37, in run_in_threadpool
    return await anyio.to_thread.run_sync(func)
           ^^^^^^^^^^^^^^^^^^^^^^^^^^^^^^^^^^^^
  File "C:\Users\zelun\AppData\Roaming\Python\Python313\site-packages\anyio\to_thread.py", line 56, in run_sync
    return await get_async_backend().run_sync_in_worker_thread(
           ^^^^^^^^^^^^^^^^^^^^^^^^^^^^^^^^^^^^^^^^^^^^^^^^^^^^
        func, args, abandon_on_cancel=abandon_on_cancel, limiter=limiter
        ^^^^^^^^^^^^^^^^^^^^^^^^^^^^^^^^^^^^^^^^^^^^^^^^^^^^^^^^^^^^^^^^
    )
    ^
  File "C:\Users\zelun\AppData\Roaming\Python\Python313\site-packages\anyio\_backends\_asyncio.py", line 2470, in run_sync_in_worker_thread
    return await future
           ^^^^^^^^^^^^
  File "C:\Users\zelun\AppData\Roaming\Python\Python313\site-packages\anyio\_backends\_asyncio.py", line 967, in run
    result = context.run(func, *args)
  File "C:\Users\zelun\Desktop\Projects\Scribsy\app\api\endpoints\patients.py", line 69, in create_patient
    return crud_patients.create_patient(db, schemas.PatientCreate(**patient_data))
           ~~~~~~~~~~~~~~~~~~~~~~~~~~~~^^^^^^^^^^^^^^^^^^^^^^^^^^^^^^^^^^^^^^^^^^^
  File "C:\Users\zelun\Desktop\Projects\Scribsy\app\crud\patients.py", line 15, in create_patient
    db.commit()
    ~~~~~~~~~^^
  File "C:\Users\zelun\AppData\Roaming\Python\Python313\site-packages\sqlalchemy\orm\session.py", line 2032, in commit
    trans.commit(_to_root=True)
    ~~~~~~~~~~~~^^^^^^^^^^^^^^^
  File "<string>", line 2, in commit
  File "C:\Users\zelun\AppData\Roaming\Python\Python313\site-packages\sqlalchemy\orm\state_changes.py", line 137, in _go
    ret_value = fn(self, *arg, **kw)
  File "C:\Users\zelun\AppData\Roaming\Python\Python313\site-packages\sqlalchemy\orm\session.py", line 1313, in commit
    self._prepare_impl()
    ~~~~~~~~~~~~~~~~~~^^
  File "<string>", line 2, in _prepare_impl
  File "C:\Users\zelun\AppData\Roaming\Python\Python313\site-packages\sqlalchemy\orm\state_changes.py", line 137, in _go
    ret_value = fn(self, *arg, **kw)
  File "C:\Users\zelun\AppData\Roaming\Python\Python313\site-packages\sqlalchemy\orm\session.py", line 1288, in _prepare_impl
    self.session.flush()
    ~~~~~~~~~~~~~~~~~~^^
  File "C:\Users\zelun\AppData\Roaming\Python\Python313\site-packages\sqlalchemy\orm\session.py", line 4345, in flush
    self._flush(objects)
    ~~~~~~~~~~~^^^^^^^^^
  File "C:\Users\zelun\AppData\Roaming\Python\Python313\site-packages\sqlalchemy\orm\session.py", line 4480, in _flush
    with util.safe_reraise():
         ~~~~~~~~~~~~~~~~~^^
  File "C:\Users\zelun\AppData\Roaming\Python\Python313\site-packages\sqlalchemy\util\langhelpers.py", line 224, in __exit__
    raise exc_value.with_traceback(exc_tb)
  File "C:\Users\zelun\AppData\Roaming\Python\Python313\site-packages\sqlalchemy\orm\session.py", line 4441, in _flush
    flush_context.execute()
    ~~~~~~~~~~~~~~~~~~~~~^^
  File "C:\Users\zelun\AppData\Roaming\Python\Python313\site-packages\sqlalchemy\orm\unitofwork.py", line 466, in execute
    rec.execute(self)
    ~~~~~~~~~~~^^^^^^
  File "C:\Users\zelun\AppData\Roaming\Python\Python313\site-packages\sqlalchemy\orm\unitofwork.py", line 642, in execute
    util.preloaded.orm_persistence.save_obj(
    ~~~~~~~~~~~~~~~~~~~~~~~~~~~~~~~~~~~~~~~^
        self.mapper,
        ^^^^^^^^^^^^
        uow.states_for_mapper_hierarchy(self.mapper, False, False),
        ^^^^^^^^^^^^^^^^^^^^^^^^^^^^^^^^^^^^^^^^^^^^^^^^^^^^^^^^^^^
        uow,
        ^^^^
    )
    ^
  File "C:\Users\zelun\AppData\Roaming\Python\Python313\site-packages\sqlalchemy\orm\persistence.py", line 93, in save_obj
    _emit_insert_statements(
    ~~~~~~~~~~~~~~~~~~~~~~~^
        base_mapper,
        ^^^^^^^^^^^^
    ...<3 lines>...
        insert,
        ^^^^^^^
    )
    ^
  File "C:\Users\zelun\AppData\Roaming\Python\Python313\site-packages\sqlalchemy\orm\persistence.py", line 1233, in _emit_insert_statements
    result = connection.execute(
        statement,
        params,
        execution_options=execution_options,
    )
  File "C:\Users\zelun\AppData\Roaming\Python\Python313\site-packages\sqlalchemy\engine\base.py", line 1413, in execute
    return meth(
        self,
        distilled_parameters,
        execution_options or NO_OPTIONS,
    )
  File "C:\Users\zelun\AppData\Roaming\Python\Python313\site-packages\sqlalchemy\sql\elements.py", line 526, in _execute_on_connection
    return connection._execute_clauseelement(
           ~~~~~~~~~~~~~~~~~~~~~~~~~~~~~~~~~^
        self, distilled_params, execution_options
        ^^^^^^^^^^^^^^^^^^^^^^^^^^^^^^^^^^^^^^^^^
    )
    ^
  File "C:\Users\zelun\AppData\Roaming\Python\Python313\site-packages\sqlalchemy\engine\base.py", line 1635, in _execute_clauseelement
    ret = self._execute_context(
        dialect,
    ...<8 lines>...
        cache_hit=cache_hit,
    )
  File "C:\Users\zelun\AppData\Roaming\Python\Python313\site-packages\sqlalchemy\engine\base.py", line 1840, in _execute_context
    return self._exec_single_context(
           ~~~~~~~~~~~~~~~~~~~~~~~~~^
        dialect, context, statement, parameters
        ^^^^^^^^^^^^^^^^^^^^^^^^^^^^^^^^^^^^^^^
    )
    ^
  File "C:\Users\zelun\AppData\Roaming\Python\Python313\site-packages\sqlalchemy\engine\base.py", line 1980, in _exec_single_context
    self._handle_dbapi_exception(
    ~~~~~~~~~~~~~~~~~~~~~~~~~~~~^
        e, str_statement, effective_parameters, cursor, context
        ^^^^^^^^^^^^^^^^^^^^^^^^^^^^^^^^^^^^^^^^^^^^^^^^^^^^^^^
    )
    ^
  File "C:\Users\zelun\AppData\Roaming\Python\Python313\site-packages\sqlalchemy\engine\base.py", line 2349, in _handle_dbapi_exception
    raise sqlalchemy_exception.with_traceback(exc_info[2]) from e
  File "C:\Users\zelun\AppData\Roaming\Python\Python313\site-packages\sqlalchemy\engine\base.py", line 1961, in _exec_single_context
    self.dialect.do_execute(
    ~~~~~~~~~~~~~~~~~~~~~~~^
        cursor, str_statement, effective_parameters, context
        ^^^^^^^^^^^^^^^^^^^^^^^^^^^^^^^^^^^^^^^^^^^^^^^^^^^^
    )
    ^
  File "C:\Users\zelun\AppData\Roaming\Python\Python313\site-packages\sqlalchemy\engine\default.py", line 944, in do_execute
    cursor.execute(statement, parameters)
    ~~~~~~~~~~~~~~^^^^^^^^^^^^^^^^^^^^^^^
sqlalchemy.exc.IntegrityError: (sqlite3.IntegrityError) NOT NULL constraint failed: patients.id
[SQL: INSERT INTO patients (user_id, first_name, last_name, date_of_birth, phone_number, email, address, city, state, zip_code, created_at, updated_at) VALUES (?, ?, ?, ?, ?, ?, ?, ?, ?, ?, ?, ?)]
[parameters: (8, 'Zelun', 'He', '1999-10-20', '314-526-1141', 'zelunhe@gmail.com', '5183 MILD DR', None, None, None, '2025-08-09 02:52:17.550704', '2025-08-09 02:52:17.550708')]
(Background on this error at: https://sqlalche.me/e/20/gkpj)
2025-08-08 22:01:01,249 - scribsy - ERROR - logging:68 - Error in Unhandled exception at: /patients/: (sqlite3.IntegrityError) NOT NULL constraint failed: patients.id
[SQL: INSERT INTO patients (user_id, first_name, last_name, date_of_birth, phone_number, email, address, city, state, zip_code, created_at, updated_at) VALUES (?, ?, ?, ?, ?, ?, ?, ?, ?, ?, ?, ?)]
[parameters: (8, 'Zelun', 'He', '1999-10-20', '314-526-1141', 'zelunhe@gmail.com', '5183 MILD DR', None, None, None, '2025-08-09 03:01:01.248465', '2025-08-09 03:01:01.248470')]
(Background on this error at: https://sqlalche.me/e/20/gkpj) - anonymous
Traceback (most recent call last):
  File "C:\Users\zelun\AppData\Roaming\Python\Python313\site-packages\sqlalchemy\engine\base.py", line 1961, in _exec_single_context
    self.dialect.do_execute(
    ~~~~~~~~~~~~~~~~~~~~~~~^
        cursor, str_statement, effective_parameters, context
        ^^^^^^^^^^^^^^^^^^^^^^^^^^^^^^^^^^^^^^^^^^^^^^^^^^^^
    )
    ^
  File "C:\Users\zelun\AppData\Roaming\Python\Python313\site-packages\sqlalchemy\engine\default.py", line 944, in do_execute
    cursor.execute(statement, parameters)
    ~~~~~~~~~~~~~~^^^^^^^^^^^^^^^^^^^^^^^
sqlite3.IntegrityError: NOT NULL constraint failed: patients.id

The above exception was the direct cause of the following exception:

Traceback (most recent call last):
  File "C:\Users\zelun\AppData\Roaming\Python\Python313\site-packages\starlette\middleware\errors.py", line 165, in __call__
    await self.app(scope, receive, _send)
  File "C:\Users\zelun\AppData\Roaming\Python\Python313\site-packages\starlette\middleware\cors.py", line 93, in __call__
    await self.simple_response(scope, receive, send, request_headers=headers)
  File "C:\Users\zelun\AppData\Roaming\Python\Python313\site-packages\starlette\middleware\cors.py", line 144, in simple_response
    await self.app(scope, receive, send)
  File "C:\Users\zelun\AppData\Roaming\Python\Python313\site-packages\starlette\middleware\exceptions.py", line 62, in __call__
    await wrap_app_handling_exceptions(self.app, conn)(scope, receive, send)
  File "C:\Users\zelun\AppData\Roaming\Python\Python313\site-packages\starlette\_exception_handler.py", line 53, in wrapped_app
    raise exc
  File "C:\Users\zelun\AppData\Roaming\Python\Python313\site-packages\starlette\_exception_handler.py", line 42, in wrapped_app
    await app(scope, receive, sender)
  File "C:\Users\zelun\AppData\Roaming\Python\Python313\site-packages\starlette\routing.py", line 714, in __call__
    await self.middleware_stack(scope, receive, send)
  File "C:\Users\zelun\AppData\Roaming\Python\Python313\site-packages\starlette\routing.py", line 734, in app
    await route.handle(scope, receive, send)
  File "C:\Users\zelun\AppData\Roaming\Python\Python313\site-packages\starlette\routing.py", line 288, in handle
    await self.app(scope, receive, send)
  File "C:\Users\zelun\AppData\Roaming\Python\Python313\site-packages\starlette\routing.py", line 76, in app
    await wrap_app_handling_exceptions(app, request)(scope, receive, send)
  File "C:\Users\zelun\AppData\Roaming\Python\Python313\site-packages\starlette\_exception_handler.py", line 53, in wrapped_app
    raise exc
  File "C:\Users\zelun\AppData\Roaming\Python\Python313\site-packages\starlette\_exception_handler.py", line 42, in wrapped_app
    await app(scope, receive, sender)
  File "C:\Users\zelun\AppData\Roaming\Python\Python313\site-packages\starlette\routing.py", line 73, in app
    response = await f(request)
               ^^^^^^^^^^^^^^^^
  File "C:\Users\zelun\AppData\Roaming\Python\Python313\site-packages\fastapi\routing.py", line 301, in app
    raw_response = await run_endpoint_function(
                   ^^^^^^^^^^^^^^^^^^^^^^^^^^^^
    ...<3 lines>...
    )
    ^
  File "C:\Users\zelun\AppData\Roaming\Python\Python313\site-packages\fastapi\routing.py", line 214, in run_endpoint_function
    return await run_in_threadpool(dependant.call, **values)
           ^^^^^^^^^^^^^^^^^^^^^^^^^^^^^^^^^^^^^^^^^^^^^^^^^
  File "C:\Users\zelun\AppData\Roaming\Python\Python313\site-packages\starlette\concurrency.py", line 37, in run_in_threadpool
    return await anyio.to_thread.run_sync(func)
           ^^^^^^^^^^^^^^^^^^^^^^^^^^^^^^^^^^^^
  File "C:\Users\zelun\AppData\Roaming\Python\Python313\site-packages\anyio\to_thread.py", line 56, in run_sync
    return await get_async_backend().run_sync_in_worker_thread(
           ^^^^^^^^^^^^^^^^^^^^^^^^^^^^^^^^^^^^^^^^^^^^^^^^^^^^
        func, args, abandon_on_cancel=abandon_on_cancel, limiter=limiter
        ^^^^^^^^^^^^^^^^^^^^^^^^^^^^^^^^^^^^^^^^^^^^^^^^^^^^^^^^^^^^^^^^
    )
    ^
  File "C:\Users\zelun\AppData\Roaming\Python\Python313\site-packages\anyio\_backends\_asyncio.py", line 2470, in run_sync_in_worker_thread
    return await future
           ^^^^^^^^^^^^
  File "C:\Users\zelun\AppData\Roaming\Python\Python313\site-packages\anyio\_backends\_asyncio.py", line 967, in run
    result = context.run(func, *args)
  File "C:\Users\zelun\Desktop\Projects\Scribsy\app\api\endpoints\patients.py", line 69, in create_patient
    return crud_patients.create_patient(db, schemas.PatientCreate(**patient_data))
           ~~~~~~~~~~~~~~~~~~~~~~~~~~~~^^^^^^^^^^^^^^^^^^^^^^^^^^^^^^^^^^^^^^^^^^^
  File "C:\Users\zelun\Desktop\Projects\Scribsy\app\crud\patients.py", line 15, in create_patient
    db.commit()
    ~~~~~~~~~^^
  File "C:\Users\zelun\AppData\Roaming\Python\Python313\site-packages\sqlalchemy\orm\session.py", line 2032, in commit
    trans.commit(_to_root=True)
    ~~~~~~~~~~~~^^^^^^^^^^^^^^^
  File "<string>", line 2, in commit
  File "C:\Users\zelun\AppData\Roaming\Python\Python313\site-packages\sqlalchemy\orm\state_changes.py", line 137, in _go
    ret_value = fn(self, *arg, **kw)
  File "C:\Users\zelun\AppData\Roaming\Python\Python313\site-packages\sqlalchemy\orm\session.py", line 1313, in commit
    self._prepare_impl()
    ~~~~~~~~~~~~~~~~~~^^
  File "<string>", line 2, in _prepare_impl
  File "C:\Users\zelun\AppData\Roaming\Python\Python313\site-packages\sqlalchemy\orm\state_changes.py", line 137, in _go
    ret_value = fn(self, *arg, **kw)
  File "C:\Users\zelun\AppData\Roaming\Python\Python313\site-packages\sqlalchemy\orm\session.py", line 1288, in _prepare_impl
    self.session.flush()
    ~~~~~~~~~~~~~~~~~~^^
  File "C:\Users\zelun\AppData\Roaming\Python\Python313\site-packages\sqlalchemy\orm\session.py", line 4345, in flush
    self._flush(objects)
    ~~~~~~~~~~~^^^^^^^^^
  File "C:\Users\zelun\AppData\Roaming\Python\Python313\site-packages\sqlalchemy\orm\session.py", line 4480, in _flush
    with util.safe_reraise():
         ~~~~~~~~~~~~~~~~~^^
  File "C:\Users\zelun\AppData\Roaming\Python\Python313\site-packages\sqlalchemy\util\langhelpers.py", line 224, in __exit__
    raise exc_value.with_traceback(exc_tb)
  File "C:\Users\zelun\AppData\Roaming\Python\Python313\site-packages\sqlalchemy\orm\session.py", line 4441, in _flush
    flush_context.execute()
    ~~~~~~~~~~~~~~~~~~~~~^^
  File "C:\Users\zelun\AppData\Roaming\Python\Python313\site-packages\sqlalchemy\orm\unitofwork.py", line 466, in execute
    rec.execute(self)
    ~~~~~~~~~~~^^^^^^
  File "C:\Users\zelun\AppData\Roaming\Python\Python313\site-packages\sqlalchemy\orm\unitofwork.py", line 642, in execute
    util.preloaded.orm_persistence.save_obj(
    ~~~~~~~~~~~~~~~~~~~~~~~~~~~~~~~~~~~~~~~^
        self.mapper,
        ^^^^^^^^^^^^
        uow.states_for_mapper_hierarchy(self.mapper, False, False),
        ^^^^^^^^^^^^^^^^^^^^^^^^^^^^^^^^^^^^^^^^^^^^^^^^^^^^^^^^^^^
        uow,
        ^^^^
    )
    ^
  File "C:\Users\zelun\AppData\Roaming\Python\Python313\site-packages\sqlalchemy\orm\persistence.py", line 93, in save_obj
    _emit_insert_statements(
    ~~~~~~~~~~~~~~~~~~~~~~~^
        base_mapper,
        ^^^^^^^^^^^^
    ...<3 lines>...
        insert,
        ^^^^^^^
    )
    ^
  File "C:\Users\zelun\AppData\Roaming\Python\Python313\site-packages\sqlalchemy\orm\persistence.py", line 1233, in _emit_insert_statements
    result = connection.execute(
        statement,
        params,
        execution_options=execution_options,
    )
  File "C:\Users\zelun\AppData\Roaming\Python\Python313\site-packages\sqlalchemy\engine\base.py", line 1413, in execute
    return meth(
        self,
        distilled_parameters,
        execution_options or NO_OPTIONS,
    )
  File "C:\Users\zelun\AppData\Roaming\Python\Python313\site-packages\sqlalchemy\sql\elements.py", line 526, in _execute_on_connection
    return connection._execute_clauseelement(
           ~~~~~~~~~~~~~~~~~~~~~~~~~~~~~~~~~^
        self, distilled_params, execution_options
        ^^^^^^^^^^^^^^^^^^^^^^^^^^^^^^^^^^^^^^^^^
    )
    ^
  File "C:\Users\zelun\AppData\Roaming\Python\Python313\site-packages\sqlalchemy\engine\base.py", line 1635, in _execute_clauseelement
    ret = self._execute_context(
        dialect,
    ...<8 lines>...
        cache_hit=cache_hit,
    )
  File "C:\Users\zelun\AppData\Roaming\Python\Python313\site-packages\sqlalchemy\engine\base.py", line 1840, in _execute_context
    return self._exec_single_context(
           ~~~~~~~~~~~~~~~~~~~~~~~~~^
        dialect, context, statement, parameters
        ^^^^^^^^^^^^^^^^^^^^^^^^^^^^^^^^^^^^^^^
    )
    ^
  File "C:\Users\zelun\AppData\Roaming\Python\Python313\site-packages\sqlalchemy\engine\base.py", line 1980, in _exec_single_context
    self._handle_dbapi_exception(
    ~~~~~~~~~~~~~~~~~~~~~~~~~~~~^
        e, str_statement, effective_parameters, cursor, context
        ^^^^^^^^^^^^^^^^^^^^^^^^^^^^^^^^^^^^^^^^^^^^^^^^^^^^^^^
    )
    ^
  File "C:\Users\zelun\AppData\Roaming\Python\Python313\site-packages\sqlalchemy\engine\base.py", line 2349, in _handle_dbapi_exception
    raise sqlalchemy_exception.with_traceback(exc_info[2]) from e
  File "C:\Users\zelun\AppData\Roaming\Python\Python313\site-packages\sqlalchemy\engine\base.py", line 1961, in _exec_single_context
    self.dialect.do_execute(
    ~~~~~~~~~~~~~~~~~~~~~~~^
        cursor, str_statement, effective_parameters, context
        ^^^^^^^^^^^^^^^^^^^^^^^^^^^^^^^^^^^^^^^^^^^^^^^^^^^^
    )
    ^
  File "C:\Users\zelun\AppData\Roaming\Python\Python313\site-packages\sqlalchemy\engine\default.py", line 944, in do_execute
    cursor.execute(statement, parameters)
    ~~~~~~~~~~~~~~^^^^^^^^^^^^^^^^^^^^^^^
sqlalchemy.exc.IntegrityError: (sqlite3.IntegrityError) NOT NULL constraint failed: patients.id
[SQL: INSERT INTO patients (user_id, first_name, last_name, date_of_birth, phone_number, email, address, city, state, zip_code, created_at, updated_at) VALUES (?, ?, ?, ?, ?, ?, ?, ?, ?, ?, ?, ?)]
[parameters: (8, 'Zelun', 'He', '1999-10-20', '314-526-1141', 'zelunhe@gmail.com', '5183 MILD DR', None, None, None, '2025-08-09 03:01:01.248465', '2025-08-09 03:01:01.248470')]
(Background on this error at: https://sqlalche.me/e/20/gkpj)
2025-08-08 22:01:02,199 - scribsy - ERROR - logging:68 - Error in Unhandled exception at: /patients/: (sqlite3.IntegrityError) NOT NULL constraint failed: patients.id
[SQL: INSERT INTO patients (user_id, first_name, last_name, date_of_birth, phone_number, email, address, city, state, zip_code, created_at, updated_at) VALUES (?, ?, ?, ?, ?, ?, ?, ?, ?, ?, ?, ?)]
[parameters: (8, 'Zelun', 'He', '1999-10-20', '314-526-1141', 'zelunhe@gmail.com', '5183 MILD DR', None, None, None, '2025-08-09 03:01:02.198293', '2025-08-09 03:01:02.198297')]
(Background on this error at: https://sqlalche.me/e/20/gkpj) - anonymous
Traceback (most recent call last):
  File "C:\Users\zelun\AppData\Roaming\Python\Python313\site-packages\sqlalchemy\engine\base.py", line 1961, in _exec_single_context
    self.dialect.do_execute(
    ~~~~~~~~~~~~~~~~~~~~~~~^
        cursor, str_statement, effective_parameters, context
        ^^^^^^^^^^^^^^^^^^^^^^^^^^^^^^^^^^^^^^^^^^^^^^^^^^^^
    )
    ^
  File "C:\Users\zelun\AppData\Roaming\Python\Python313\site-packages\sqlalchemy\engine\default.py", line 944, in do_execute
    cursor.execute(statement, parameters)
    ~~~~~~~~~~~~~~^^^^^^^^^^^^^^^^^^^^^^^
sqlite3.IntegrityError: NOT NULL constraint failed: patients.id

The above exception was the direct cause of the following exception:

Traceback (most recent call last):
  File "C:\Users\zelun\AppData\Roaming\Python\Python313\site-packages\starlette\middleware\errors.py", line 165, in __call__
    await self.app(scope, receive, _send)
  File "C:\Users\zelun\AppData\Roaming\Python\Python313\site-packages\starlette\middleware\cors.py", line 93, in __call__
    await self.simple_response(scope, receive, send, request_headers=headers)
  File "C:\Users\zelun\AppData\Roaming\Python\Python313\site-packages\starlette\middleware\cors.py", line 144, in simple_response
    await self.app(scope, receive, send)
  File "C:\Users\zelun\AppData\Roaming\Python\Python313\site-packages\starlette\middleware\exceptions.py", line 62, in __call__
    await wrap_app_handling_exceptions(self.app, conn)(scope, receive, send)
  File "C:\Users\zelun\AppData\Roaming\Python\Python313\site-packages\starlette\_exception_handler.py", line 53, in wrapped_app
    raise exc
  File "C:\Users\zelun\AppData\Roaming\Python\Python313\site-packages\starlette\_exception_handler.py", line 42, in wrapped_app
    await app(scope, receive, sender)
  File "C:\Users\zelun\AppData\Roaming\Python\Python313\site-packages\starlette\routing.py", line 714, in __call__
    await self.middleware_stack(scope, receive, send)
  File "C:\Users\zelun\AppData\Roaming\Python\Python313\site-packages\starlette\routing.py", line 734, in app
    await route.handle(scope, receive, send)
  File "C:\Users\zelun\AppData\Roaming\Python\Python313\site-packages\starlette\routing.py", line 288, in handle
    await self.app(scope, receive, send)
  File "C:\Users\zelun\AppData\Roaming\Python\Python313\site-packages\starlette\routing.py", line 76, in app
    await wrap_app_handling_exceptions(app, request)(scope, receive, send)
  File "C:\Users\zelun\AppData\Roaming\Python\Python313\site-packages\starlette\_exception_handler.py", line 53, in wrapped_app
    raise exc
  File "C:\Users\zelun\AppData\Roaming\Python\Python313\site-packages\starlette\_exception_handler.py", line 42, in wrapped_app
    await app(scope, receive, sender)
  File "C:\Users\zelun\AppData\Roaming\Python\Python313\site-packages\starlette\routing.py", line 73, in app
    response = await f(request)
               ^^^^^^^^^^^^^^^^
  File "C:\Users\zelun\AppData\Roaming\Python\Python313\site-packages\fastapi\routing.py", line 301, in app
    raw_response = await run_endpoint_function(
                   ^^^^^^^^^^^^^^^^^^^^^^^^^^^^
    ...<3 lines>...
    )
    ^
  File "C:\Users\zelun\AppData\Roaming\Python\Python313\site-packages\fastapi\routing.py", line 214, in run_endpoint_function
    return await run_in_threadpool(dependant.call, **values)
           ^^^^^^^^^^^^^^^^^^^^^^^^^^^^^^^^^^^^^^^^^^^^^^^^^
  File "C:\Users\zelun\AppData\Roaming\Python\Python313\site-packages\starlette\concurrency.py", line 37, in run_in_threadpool
    return await anyio.to_thread.run_sync(func)
           ^^^^^^^^^^^^^^^^^^^^^^^^^^^^^^^^^^^^
  File "C:\Users\zelun\AppData\Roaming\Python\Python313\site-packages\anyio\to_thread.py", line 56, in run_sync
    return await get_async_backend().run_sync_in_worker_thread(
           ^^^^^^^^^^^^^^^^^^^^^^^^^^^^^^^^^^^^^^^^^^^^^^^^^^^^
        func, args, abandon_on_cancel=abandon_on_cancel, limiter=limiter
        ^^^^^^^^^^^^^^^^^^^^^^^^^^^^^^^^^^^^^^^^^^^^^^^^^^^^^^^^^^^^^^^^
    )
    ^
  File "C:\Users\zelun\AppData\Roaming\Python\Python313\site-packages\anyio\_backends\_asyncio.py", line 2470, in run_sync_in_worker_thread
    return await future
           ^^^^^^^^^^^^
  File "C:\Users\zelun\AppData\Roaming\Python\Python313\site-packages\anyio\_backends\_asyncio.py", line 967, in run
    result = context.run(func, *args)
  File "C:\Users\zelun\Desktop\Projects\Scribsy\app\api\endpoints\patients.py", line 69, in create_patient
    return crud_patients.create_patient(db, schemas.PatientCreate(**patient_data))
           ~~~~~~~~~~~~~~~~~~~~~~~~~~~~^^^^^^^^^^^^^^^^^^^^^^^^^^^^^^^^^^^^^^^^^^^
  File "C:\Users\zelun\Desktop\Projects\Scribsy\app\crud\patients.py", line 15, in create_patient
    db.commit()
    ~~~~~~~~~^^
  File "C:\Users\zelun\AppData\Roaming\Python\Python313\site-packages\sqlalchemy\orm\session.py", line 2032, in commit
    trans.commit(_to_root=True)
    ~~~~~~~~~~~~^^^^^^^^^^^^^^^
  File "<string>", line 2, in commit
  File "C:\Users\zelun\AppData\Roaming\Python\Python313\site-packages\sqlalchemy\orm\state_changes.py", line 137, in _go
    ret_value = fn(self, *arg, **kw)
  File "C:\Users\zelun\AppData\Roaming\Python\Python313\site-packages\sqlalchemy\orm\session.py", line 1313, in commit
    self._prepare_impl()
    ~~~~~~~~~~~~~~~~~~^^
  File "<string>", line 2, in _prepare_impl
  File "C:\Users\zelun\AppData\Roaming\Python\Python313\site-packages\sqlalchemy\orm\state_changes.py", line 137, in _go
    ret_value = fn(self, *arg, **kw)
  File "C:\Users\zelun\AppData\Roaming\Python\Python313\site-packages\sqlalchemy\orm\session.py", line 1288, in _prepare_impl
    self.session.flush()
    ~~~~~~~~~~~~~~~~~~^^
  File "C:\Users\zelun\AppData\Roaming\Python\Python313\site-packages\sqlalchemy\orm\session.py", line 4345, in flush
    self._flush(objects)
    ~~~~~~~~~~~^^^^^^^^^
  File "C:\Users\zelun\AppData\Roaming\Python\Python313\site-packages\sqlalchemy\orm\session.py", line 4480, in _flush
    with util.safe_reraise():
         ~~~~~~~~~~~~~~~~~^^
  File "C:\Users\zelun\AppData\Roaming\Python\Python313\site-packages\sqlalchemy\util\langhelpers.py", line 224, in __exit__
    raise exc_value.with_traceback(exc_tb)
  File "C:\Users\zelun\AppData\Roaming\Python\Python313\site-packages\sqlalchemy\orm\session.py", line 4441, in _flush
    flush_context.execute()
    ~~~~~~~~~~~~~~~~~~~~~^^
  File "C:\Users\zelun\AppData\Roaming\Python\Python313\site-packages\sqlalchemy\orm\unitofwork.py", line 466, in execute
    rec.execute(self)
    ~~~~~~~~~~~^^^^^^
  File "C:\Users\zelun\AppData\Roaming\Python\Python313\site-packages\sqlalchemy\orm\unitofwork.py", line 642, in execute
    util.preloaded.orm_persistence.save_obj(
    ~~~~~~~~~~~~~~~~~~~~~~~~~~~~~~~~~~~~~~~^
        self.mapper,
        ^^^^^^^^^^^^
        uow.states_for_mapper_hierarchy(self.mapper, False, False),
        ^^^^^^^^^^^^^^^^^^^^^^^^^^^^^^^^^^^^^^^^^^^^^^^^^^^^^^^^^^^
        uow,
        ^^^^
    )
    ^
  File "C:\Users\zelun\AppData\Roaming\Python\Python313\site-packages\sqlalchemy\orm\persistence.py", line 93, in save_obj
    _emit_insert_statements(
    ~~~~~~~~~~~~~~~~~~~~~~~^
        base_mapper,
        ^^^^^^^^^^^^
    ...<3 lines>...
        insert,
        ^^^^^^^
    )
    ^
  File "C:\Users\zelun\AppData\Roaming\Python\Python313\site-packages\sqlalchemy\orm\persistence.py", line 1233, in _emit_insert_statements
    result = connection.execute(
        statement,
        params,
        execution_options=execution_options,
    )
  File "C:\Users\zelun\AppData\Roaming\Python\Python313\site-packages\sqlalchemy\engine\base.py", line 1413, in execute
    return meth(
        self,
        distilled_parameters,
        execution_options or NO_OPTIONS,
    )
  File "C:\Users\zelun\AppData\Roaming\Python\Python313\site-packages\sqlalchemy\sql\elements.py", line 526, in _execute_on_connection
    return connection._execute_clauseelement(
           ~~~~~~~~~~~~~~~~~~~~~~~~~~~~~~~~~^
        self, distilled_params, execution_options
        ^^^^^^^^^^^^^^^^^^^^^^^^^^^^^^^^^^^^^^^^^
    )
    ^
  File "C:\Users\zelun\AppData\Roaming\Python\Python313\site-packages\sqlalchemy\engine\base.py", line 1635, in _execute_clauseelement
    ret = self._execute_context(
        dialect,
    ...<8 lines>...
        cache_hit=cache_hit,
    )
  File "C:\Users\zelun\AppData\Roaming\Python\Python313\site-packages\sqlalchemy\engine\base.py", line 1840, in _execute_context
    return self._exec_single_context(
           ~~~~~~~~~~~~~~~~~~~~~~~~~^
        dialect, context, statement, parameters
        ^^^^^^^^^^^^^^^^^^^^^^^^^^^^^^^^^^^^^^^
    )
    ^
  File "C:\Users\zelun\AppData\Roaming\Python\Python313\site-packages\sqlalchemy\engine\base.py", line 1980, in _exec_single_context
    self._handle_dbapi_exception(
    ~~~~~~~~~~~~~~~~~~~~~~~~~~~~^
        e, str_statement, effective_parameters, cursor, context
        ^^^^^^^^^^^^^^^^^^^^^^^^^^^^^^^^^^^^^^^^^^^^^^^^^^^^^^^
    )
    ^
  File "C:\Users\zelun\AppData\Roaming\Python\Python313\site-packages\sqlalchemy\engine\base.py", line 2349, in _handle_dbapi_exception
    raise sqlalchemy_exception.with_traceback(exc_info[2]) from e
  File "C:\Users\zelun\AppData\Roaming\Python\Python313\site-packages\sqlalchemy\engine\base.py", line 1961, in _exec_single_context
    self.dialect.do_execute(
    ~~~~~~~~~~~~~~~~~~~~~~~^
        cursor, str_statement, effective_parameters, context
        ^^^^^^^^^^^^^^^^^^^^^^^^^^^^^^^^^^^^^^^^^^^^^^^^^^^^
    )
    ^
  File "C:\Users\zelun\AppData\Roaming\Python\Python313\site-packages\sqlalchemy\engine\default.py", line 944, in do_execute
    cursor.execute(statement, parameters)
    ~~~~~~~~~~~~~~^^^^^^^^^^^^^^^^^^^^^^^
sqlalchemy.exc.IntegrityError: (sqlite3.IntegrityError) NOT NULL constraint failed: patients.id
[SQL: INSERT INTO patients (user_id, first_name, last_name, date_of_birth, phone_number, email, address, city, state, zip_code, created_at, updated_at) VALUES (?, ?, ?, ?, ?, ?, ?, ?, ?, ?, ?, ?)]
[parameters: (8, 'Zelun', 'He', '1999-10-20', '314-526-1141', 'zelunhe@gmail.com', '5183 MILD DR', None, None, None, '2025-08-09 03:01:02.198293', '2025-08-09 03:01:02.198297')]
(Background on this error at: https://sqlalche.me/e/20/gkpj)
2025-08-08 22:01:58,603 - scribsy - ERROR - logging:68 - Error in Unhandled exception at: /patients/: (sqlite3.IntegrityError) NOT NULL constraint failed: patients.id
[SQL: INSERT INTO patients (user_id, first_name, last_name, date_of_birth, phone_number, email, address, city, state, zip_code, created_at, updated_at) VALUES (?, ?, ?, ?, ?, ?, ?, ?, ?, ?, ?, ?)]
[parameters: (10, 'Test', 'Patient', '1990-01-01', None, None, None, None, None, None, '2025-08-09 03:01:58.603016', '2025-08-09 03:01:58.603020')]
(Background on this error at: https://sqlalche.me/e/20/gkpj) - anonymous
Traceback (most recent call last):
  File "C:\Users\zelun\AppData\Roaming\Python\Python313\site-packages\sqlalchemy\engine\base.py", line 1961, in _exec_single_context
    self.dialect.do_execute(
    ~~~~~~~~~~~~~~~~~~~~~~~^
        cursor, str_statement, effective_parameters, context
        ^^^^^^^^^^^^^^^^^^^^^^^^^^^^^^^^^^^^^^^^^^^^^^^^^^^^
    )
    ^
  File "C:\Users\zelun\AppData\Roaming\Python\Python313\site-packages\sqlalchemy\engine\default.py", line 944, in do_execute
    cursor.execute(statement, parameters)
    ~~~~~~~~~~~~~~^^^^^^^^^^^^^^^^^^^^^^^
sqlite3.IntegrityError: NOT NULL constraint failed: patients.id

The above exception was the direct cause of the following exception:

Traceback (most recent call last):
  File "C:\Users\zelun\AppData\Roaming\Python\Python313\site-packages\starlette\middleware\errors.py", line 165, in __call__
    await self.app(scope, receive, _send)
  File "C:\Users\zelun\AppData\Roaming\Python\Python313\site-packages\starlette\middleware\cors.py", line 85, in __call__
    await self.app(scope, receive, send)
  File "C:\Users\zelun\AppData\Roaming\Python\Python313\site-packages\starlette\middleware\exceptions.py", line 62, in __call__
    await wrap_app_handling_exceptions(self.app, conn)(scope, receive, send)
  File "C:\Users\zelun\AppData\Roaming\Python\Python313\site-packages\starlette\_exception_handler.py", line 53, in wrapped_app
    raise exc
  File "C:\Users\zelun\AppData\Roaming\Python\Python313\site-packages\starlette\_exception_handler.py", line 42, in wrapped_app
    await app(scope, receive, sender)
  File "C:\Users\zelun\AppData\Roaming\Python\Python313\site-packages\starlette\routing.py", line 714, in __call__
    await self.middleware_stack(scope, receive, send)
  File "C:\Users\zelun\AppData\Roaming\Python\Python313\site-packages\starlette\routing.py", line 734, in app
    await route.handle(scope, receive, send)
  File "C:\Users\zelun\AppData\Roaming\Python\Python313\site-packages\starlette\routing.py", line 288, in handle
    await self.app(scope, receive, send)
  File "C:\Users\zelun\AppData\Roaming\Python\Python313\site-packages\starlette\routing.py", line 76, in app
    await wrap_app_handling_exceptions(app, request)(scope, receive, send)
  File "C:\Users\zelun\AppData\Roaming\Python\Python313\site-packages\starlette\_exception_handler.py", line 53, in wrapped_app
    raise exc
  File "C:\Users\zelun\AppData\Roaming\Python\Python313\site-packages\starlette\_exception_handler.py", line 42, in wrapped_app
    await app(scope, receive, sender)
  File "C:\Users\zelun\AppData\Roaming\Python\Python313\site-packages\starlette\routing.py", line 73, in app
    response = await f(request)
               ^^^^^^^^^^^^^^^^
  File "C:\Users\zelun\AppData\Roaming\Python\Python313\site-packages\fastapi\routing.py", line 301, in app
    raw_response = await run_endpoint_function(
                   ^^^^^^^^^^^^^^^^^^^^^^^^^^^^
    ...<3 lines>...
    )
    ^
  File "C:\Users\zelun\AppData\Roaming\Python\Python313\site-packages\fastapi\routing.py", line 214, in run_endpoint_function
    return await run_in_threadpool(dependant.call, **values)
           ^^^^^^^^^^^^^^^^^^^^^^^^^^^^^^^^^^^^^^^^^^^^^^^^^
  File "C:\Users\zelun\AppData\Roaming\Python\Python313\site-packages\starlette\concurrency.py", line 37, in run_in_threadpool
    return await anyio.to_thread.run_sync(func)
           ^^^^^^^^^^^^^^^^^^^^^^^^^^^^^^^^^^^^
  File "C:\Users\zelun\AppData\Roaming\Python\Python313\site-packages\anyio\to_thread.py", line 56, in run_sync
    return await get_async_backend().run_sync_in_worker_thread(
           ^^^^^^^^^^^^^^^^^^^^^^^^^^^^^^^^^^^^^^^^^^^^^^^^^^^^
        func, args, abandon_on_cancel=abandon_on_cancel, limiter=limiter
        ^^^^^^^^^^^^^^^^^^^^^^^^^^^^^^^^^^^^^^^^^^^^^^^^^^^^^^^^^^^^^^^^
    )
    ^
  File "C:\Users\zelun\AppData\Roaming\Python\Python313\site-packages\anyio\_backends\_asyncio.py", line 2470, in run_sync_in_worker_thread
    return await future
           ^^^^^^^^^^^^
  File "C:\Users\zelun\AppData\Roaming\Python\Python313\site-packages\anyio\_backends\_asyncio.py", line 967, in run
    result = context.run(func, *args)
  File "C:\Users\zelun\Desktop\Projects\Scribsy\app\api\endpoints\patients.py", line 69, in create_patient
    return crud_patients.create_patient(db, schemas.PatientCreate(**patient_data))
           ~~~~~~~~~~~~~~~~~~~~~~~~~~~~^^^^^^^^^^^^^^^^^^^^^^^^^^^^^^^^^^^^^^^^^^^
  File "C:\Users\zelun\Desktop\Projects\Scribsy\app\crud\patients.py", line 15, in create_patient
    db.commit()
    ~~~~~~~~~^^
  File "C:\Users\zelun\AppData\Roaming\Python\Python313\site-packages\sqlalchemy\orm\session.py", line 2032, in commit
    trans.commit(_to_root=True)
    ~~~~~~~~~~~~^^^^^^^^^^^^^^^
  File "<string>", line 2, in commit
  File "C:\Users\zelun\AppData\Roaming\Python\Python313\site-packages\sqlalchemy\orm\state_changes.py", line 137, in _go
    ret_value = fn(self, *arg, **kw)
  File "C:\Users\zelun\AppData\Roaming\Python\Python313\site-packages\sqlalchemy\orm\session.py", line 1313, in commit
    self._prepare_impl()
    ~~~~~~~~~~~~~~~~~~^^
  File "<string>", line 2, in _prepare_impl
  File "C:\Users\zelun\AppData\Roaming\Python\Python313\site-packages\sqlalchemy\orm\state_changes.py", line 137, in _go
    ret_value = fn(self, *arg, **kw)
  File "C:\Users\zelun\AppData\Roaming\Python\Python313\site-packages\sqlalchemy\orm\session.py", line 1288, in _prepare_impl
    self.session.flush()
    ~~~~~~~~~~~~~~~~~~^^
  File "C:\Users\zelun\AppData\Roaming\Python\Python313\site-packages\sqlalchemy\orm\session.py", line 4345, in flush
    self._flush(objects)
    ~~~~~~~~~~~^^^^^^^^^
  File "C:\Users\zelun\AppData\Roaming\Python\Python313\site-packages\sqlalchemy\orm\session.py", line 4480, in _flush
    with util.safe_reraise():
         ~~~~~~~~~~~~~~~~~^^
  File "C:\Users\zelun\AppData\Roaming\Python\Python313\site-packages\sqlalchemy\util\langhelpers.py", line 224, in __exit__
    raise exc_value.with_traceback(exc_tb)
  File "C:\Users\zelun\AppData\Roaming\Python\Python313\site-packages\sqlalchemy\orm\session.py", line 4441, in _flush
    flush_context.execute()
    ~~~~~~~~~~~~~~~~~~~~~^^
  File "C:\Users\zelun\AppData\Roaming\Python\Python313\site-packages\sqlalchemy\orm\unitofwork.py", line 466, in execute
    rec.execute(self)
    ~~~~~~~~~~~^^^^^^
  File "C:\Users\zelun\AppData\Roaming\Python\Python313\site-packages\sqlalchemy\orm\unitofwork.py", line 642, in execute
    util.preloaded.orm_persistence.save_obj(
    ~~~~~~~~~~~~~~~~~~~~~~~~~~~~~~~~~~~~~~~^
        self.mapper,
        ^^^^^^^^^^^^
        uow.states_for_mapper_hierarchy(self.mapper, False, False),
        ^^^^^^^^^^^^^^^^^^^^^^^^^^^^^^^^^^^^^^^^^^^^^^^^^^^^^^^^^^^
        uow,
        ^^^^
    )
    ^
  File "C:\Users\zelun\AppData\Roaming\Python\Python313\site-packages\sqlalchemy\orm\persistence.py", line 93, in save_obj
    _emit_insert_statements(
    ~~~~~~~~~~~~~~~~~~~~~~~^
        base_mapper,
        ^^^^^^^^^^^^
    ...<3 lines>...
        insert,
        ^^^^^^^
    )
    ^
  File "C:\Users\zelun\AppData\Roaming\Python\Python313\site-packages\sqlalchemy\orm\persistence.py", line 1233, in _emit_insert_statements
    result = connection.execute(
        statement,
        params,
        execution_options=execution_options,
    )
  File "C:\Users\zelun\AppData\Roaming\Python\Python313\site-packages\sqlalchemy\engine\base.py", line 1413, in execute
    return meth(
        self,
        distilled_parameters,
        execution_options or NO_OPTIONS,
    )
  File "C:\Users\zelun\AppData\Roaming\Python\Python313\site-packages\sqlalchemy\sql\elements.py", line 526, in _execute_on_connection
    return connection._execute_clauseelement(
           ~~~~~~~~~~~~~~~~~~~~~~~~~~~~~~~~~^
        self, distilled_params, execution_options
        ^^^^^^^^^^^^^^^^^^^^^^^^^^^^^^^^^^^^^^^^^
    )
    ^
  File "C:\Users\zelun\AppData\Roaming\Python\Python313\site-packages\sqlalchemy\engine\base.py", line 1635, in _execute_clauseelement
    ret = self._execute_context(
        dialect,
    ...<8 lines>...
        cache_hit=cache_hit,
    )
  File "C:\Users\zelun\AppData\Roaming\Python\Python313\site-packages\sqlalchemy\engine\base.py", line 1840, in _execute_context
    return self._exec_single_context(
           ~~~~~~~~~~~~~~~~~~~~~~~~~^
        dialect, context, statement, parameters
        ^^^^^^^^^^^^^^^^^^^^^^^^^^^^^^^^^^^^^^^
    )
    ^
  File "C:\Users\zelun\AppData\Roaming\Python\Python313\site-packages\sqlalchemy\engine\base.py", line 1980, in _exec_single_context
    self._handle_dbapi_exception(
    ~~~~~~~~~~~~~~~~~~~~~~~~~~~~^
        e, str_statement, effective_parameters, cursor, context
        ^^^^^^^^^^^^^^^^^^^^^^^^^^^^^^^^^^^^^^^^^^^^^^^^^^^^^^^
    )
    ^
  File "C:\Users\zelun\AppData\Roaming\Python\Python313\site-packages\sqlalchemy\engine\base.py", line 2349, in _handle_dbapi_exception
    raise sqlalchemy_exception.with_traceback(exc_info[2]) from e
  File "C:\Users\zelun\AppData\Roaming\Python\Python313\site-packages\sqlalchemy\engine\base.py", line 1961, in _exec_single_context
    self.dialect.do_execute(
    ~~~~~~~~~~~~~~~~~~~~~~~^
        cursor, str_statement, effective_parameters, context
        ^^^^^^^^^^^^^^^^^^^^^^^^^^^^^^^^^^^^^^^^^^^^^^^^^^^^
    )
    ^
  File "C:\Users\zelun\AppData\Roaming\Python\Python313\site-packages\sqlalchemy\engine\default.py", line 944, in do_execute
    cursor.execute(statement, parameters)
    ~~~~~~~~~~~~~~^^^^^^^^^^^^^^^^^^^^^^^
sqlalchemy.exc.IntegrityError: (sqlite3.IntegrityError) NOT NULL constraint failed: patients.id
[SQL: INSERT INTO patients (user_id, first_name, last_name, date_of_birth, phone_number, email, address, city, state, zip_code, created_at, updated_at) VALUES (?, ?, ?, ?, ?, ?, ?, ?, ?, ?, ?, ?)]
[parameters: (10, 'Test', 'Patient', '1990-01-01', None, None, None, None, None, None, '2025-08-09 03:01:58.603016', '2025-08-09 03:01:58.603020')]
(Background on this error at: https://sqlalche.me/e/20/gkpj)
