2025-08-19 14:22:49,276 - scribsy - ERROR - logging:68 - Error in Unhandled exception at: /notes/: (sqlite3.OperationalError) no such column: notes.s3_key
[SQL: SELECT notes.id AS notes_id, notes.patient_id AS notes_patient_id, notes.provider_id AS notes_provider_id, notes.visit_id AS notes_visit_id, notes.note_type AS notes_note_type, notes.content AS notes_content, notes.created_at AS notes_created_at, notes.updated_at AS notes_updated_at, notes.signed_at AS notes_signed_at, notes.status AS notes_status, notes.audio_file AS notes_audio_file, notes.s3_key AS notes_s3_key, notes.file_size AS notes_file_size, notes.content_type AS notes_content_type, notes.storage_provider AS notes_storage_provider 
FROM notes 
WHERE notes.provider_id = ?
 LIMIT ? OFFSET ?]
[parameters: (8, 10, 0)]
(Background on this error at: https://sqlalche.me/e/20/e3q8) - anonymous
Traceback (most recent call last):
  File "C:\Users\zelun\Desktop\Projects\Scribsy\venv\Lib\site-packages\sqlalchemy\engine\base.py", line 1963, in _exec_single_context
    self.dialect.do_execute(
  File "C:\Users\zelun\Desktop\Projects\Scribsy\venv\Lib\site-packages\sqlalchemy\engine\default.py", line 943, in do_execute
    cursor.execute(statement, parameters)
sqlite3.OperationalError: no such column: notes.s3_key

The above exception was the direct cause of the following exception:

Traceback (most recent call last):
  File "C:\Users\zelun\Desktop\Projects\Scribsy\venv\Lib\site-packages\starlette\middleware\errors.py", line 165, in __call__
    await self.app(scope, receive, _send)
  File "C:\Users\zelun\Desktop\Projects\Scribsy\venv\Lib\site-packages\starlette\middleware\cors.py", line 93, in __call__
    await self.simple_response(scope, receive, send, request_headers=headers)
  File "C:\Users\zelun\Desktop\Projects\Scribsy\venv\Lib\site-packages\starlette\middleware\cors.py", line 144, in simple_response
    await self.app(scope, receive, send)
  File "C:\Users\zelun\Desktop\Projects\Scribsy\venv\Lib\site-packages\starlette\middleware\exceptions.py", line 62, in __call__
    await wrap_app_handling_exceptions(self.app, conn)(scope, receive, send)
  File "C:\Users\zelun\Desktop\Projects\Scribsy\venv\Lib\site-packages\starlette\_exception_handler.py", line 53, in wrapped_app
    raise exc
  File "C:\Users\zelun\Desktop\Projects\Scribsy\venv\Lib\site-packages\starlette\_exception_handler.py", line 42, in wrapped_app
    await app(scope, receive, sender)
  File "C:\Users\zelun\Desktop\Projects\Scribsy\venv\Lib\site-packages\starlette\routing.py", line 714, in __call__
    await self.middleware_stack(scope, receive, send)
  File "C:\Users\zelun\Desktop\Projects\Scribsy\venv\Lib\site-packages\starlette\routing.py", line 734, in app
    await route.handle(scope, receive, send)
  File "C:\Users\zelun\Desktop\Projects\Scribsy\venv\Lib\site-packages\starlette\routing.py", line 288, in handle
    await self.app(scope, receive, send)
  File "C:\Users\zelun\Desktop\Projects\Scribsy\venv\Lib\site-packages\starlette\routing.py", line 76, in app
    await wrap_app_handling_exceptions(app, request)(scope, receive, send)
  File "C:\Users\zelun\Desktop\Projects\Scribsy\venv\Lib\site-packages\starlette\_exception_handler.py", line 53, in wrapped_app
    raise exc
  File "C:\Users\zelun\Desktop\Projects\Scribsy\venv\Lib\site-packages\starlette\_exception_handler.py", line 42, in wrapped_app
    await app(scope, receive, sender)
  File "C:\Users\zelun\Desktop\Projects\Scribsy\venv\Lib\site-packages\starlette\routing.py", line 73, in app
    response = await f(request)
               ^^^^^^^^^^^^^^^^
  File "C:\Users\zelun\AppData\Local\Programs\Python\Python311\Lib\contextlib.py", line 222, in __aexit__
    await self.gen.athrow(typ, value, traceback)
  File "C:\Users\zelun\Desktop\Projects\Scribsy\venv\Lib\site-packages\fastapi\concurrency.py", line 35, in contextmanager_in_threadpool
    raise e
  File "C:\Users\zelun\Desktop\Projects\Scribsy\venv\Lib\site-packages\fastapi\concurrency.py", line 27, in contextmanager_in_threadpool
    yield await run_in_threadpool(cm.__enter__)
  File "C:\Users\zelun\Desktop\Projects\Scribsy\venv\Lib\site-packages\fastapi\routing.py", line 301, in app
    raw_response = await run_endpoint_function(
                   ^^^^^^^^^^^^^^^^^^^^^^^^^^^^
  File "C:\Users\zelun\Desktop\Projects\Scribsy\venv\Lib\site-packages\fastapi\routing.py", line 214, in run_endpoint_function
    return await run_in_threadpool(dependant.call, **values)
           ^^^^^^^^^^^^^^^^^^^^^^^^^^^^^^^^^^^^^^^^^^^^^^^^^
  File "C:\Users\zelun\Desktop\Projects\Scribsy\venv\Lib\site-packages\starlette\concurrency.py", line 37, in run_in_threadpool
    return await anyio.to_thread.run_sync(func)
           ^^^^^^^^^^^^^^^^^^^^^^^^^^^^^^^^^^^^
  File "C:\Users\zelun\Desktop\Projects\Scribsy\venv\Lib\site-packages\anyio\to_thread.py", line 56, in run_sync
    return await get_async_backend().run_sync_in_worker_thread(
           ^^^^^^^^^^^^^^^^^^^^^^^^^^^^^^^^^^^^^^^^^^^^^^^^^^^^
  File "C:\Users\zelun\Desktop\Projects\Scribsy\venv\Lib\site-packages\anyio\_backends\_asyncio.py", line 2470, in run_sync_in_worker_thread
    return await future
           ^^^^^^^^^^^^
  File "C:\Users\zelun\Desktop\Projects\Scribsy\venv\Lib\site-packages\anyio\_backends\_asyncio.py", line 967, in run
    result = context.run(func, *args)
             ^^^^^^^^^^^^^^^^^^^^^^^^
  File "C:\Users\zelun\Desktop\Projects\Scribsy\app\api\endpoints\notes.py", line 161, in read_notes
    return crud_notes.get_notes(
           ^^^^^^^^^^^^^^^^^^^^^
  File "C:\Users\zelun\Desktop\Projects\Scribsy\app\crud\notes.py", line 88, in get_notes
    return query.offset(skip).limit(limit).all()
           ^^^^^^^^^^^^^^^^^^^^^^^^^^^^^^^^^^^^^
  File "C:\Users\zelun\Desktop\Projects\Scribsy\venv\Lib\site-packages\sqlalchemy\orm\query.py", line 2704, in all
    return self._iter().all()  # type: ignore
           ^^^^^^^^^^^^
  File "C:\Users\zelun\Desktop\Projects\Scribsy\venv\Lib\site-packages\sqlalchemy\orm\query.py", line 2857, in _iter
    result: Union[ScalarResult[_T], Result[_T]] = self.session.execute(
                                                  ^^^^^^^^^^^^^^^^^^^^^
  File "C:\Users\zelun\Desktop\Projects\Scribsy\venv\Lib\site-packages\sqlalchemy\orm\session.py", line 2365, in execute
    return self._execute_internal(
           ^^^^^^^^^^^^^^^^^^^^^^^
  File "C:\Users\zelun\Desktop\Projects\Scribsy\venv\Lib\site-packages\sqlalchemy\orm\session.py", line 2251, in _execute_internal
    result: Result[Any] = compile_state_cls.orm_execute_statement(
                          ^^^^^^^^^^^^^^^^^^^^^^^^^^^^^^^^^^^^^^^^
  File "C:\Users\zelun\Desktop\Projects\Scribsy\venv\Lib\site-packages\sqlalchemy\orm\context.py", line 306, in orm_execute_statement
    result = conn.execute(
             ^^^^^^^^^^^^^
  File "C:\Users\zelun\Desktop\Projects\Scribsy\venv\Lib\site-packages\sqlalchemy\engine\base.py", line 1415, in execute
    return meth(
           ^^^^^
  File "C:\Users\zelun\Desktop\Projects\Scribsy\venv\Lib\site-packages\sqlalchemy\sql\elements.py", line 523, in _execute_on_connection
    return connection._execute_clauseelement(
           ^^^^^^^^^^^^^^^^^^^^^^^^^^^^^^^^^^
  File "C:\Users\zelun\Desktop\Projects\Scribsy\venv\Lib\site-packages\sqlalchemy\engine\base.py", line 1637, in _execute_clauseelement
    ret = self._execute_context(
          ^^^^^^^^^^^^^^^^^^^^^^
  File "C:\Users\zelun\Desktop\Projects\Scribsy\venv\Lib\site-packages\sqlalchemy\engine\base.py", line 1842, in _execute_context
    return self._exec_single_context(
           ^^^^^^^^^^^^^^^^^^^^^^^^^^
  File "C:\Users\zelun\Desktop\Projects\Scribsy\venv\Lib\site-packages\sqlalchemy\engine\base.py", line 1982, in _exec_single_context
    self._handle_dbapi_exception(
  File "C:\Users\zelun\Desktop\Projects\Scribsy\venv\Lib\site-packages\sqlalchemy\engine\base.py", line 2351, in _handle_dbapi_exception
    raise sqlalchemy_exception.with_traceback(exc_info[2]) from e
  File "C:\Users\zelun\Desktop\Projects\Scribsy\venv\Lib\site-packages\sqlalchemy\engine\base.py", line 1963, in _exec_single_context
    self.dialect.do_execute(
  File "C:\Users\zelun\Desktop\Projects\Scribsy\venv\Lib\site-packages\sqlalchemy\engine\default.py", line 943, in do_execute
    cursor.execute(statement, parameters)
sqlalchemy.exc.OperationalError: (sqlite3.OperationalError) no such column: notes.s3_key
[SQL: SELECT notes.id AS notes_id, notes.patient_id AS notes_patient_id, notes.provider_id AS notes_provider_id, notes.visit_id AS notes_visit_id, notes.note_type AS notes_note_type, notes.content AS notes_content, notes.created_at AS notes_created_at, notes.updated_at AS notes_updated_at, notes.signed_at AS notes_signed_at, notes.status AS notes_status, notes.audio_file AS notes_audio_file, notes.s3_key AS notes_s3_key, notes.file_size AS notes_file_size, notes.content_type AS notes_content_type, notes.storage_provider AS notes_storage_provider 
FROM notes 
WHERE notes.provider_id = ?
 LIMIT ? OFFSET ?]
[parameters: (8, 10, 0)]
(Background on this error at: https://sqlalche.me/e/20/e3q8)
2025-08-19 14:22:49,669 - scribsy - ERROR - logging:68 - Error in Unhandled exception at: /notes/: (sqlite3.OperationalError) no such column: notes.s3_key
[SQL: SELECT notes.id AS notes_id, notes.patient_id AS notes_patient_id, notes.provider_id AS notes_provider_id, notes.visit_id AS notes_visit_id, notes.note_type AS notes_note_type, notes.content AS notes_content, notes.created_at AS notes_created_at, notes.updated_at AS notes_updated_at, notes.signed_at AS notes_signed_at, notes.status AS notes_status, notes.audio_file AS notes_audio_file, notes.s3_key AS notes_s3_key, notes.file_size AS notes_file_size, notes.content_type AS notes_content_type, notes.storage_provider AS notes_storage_provider 
FROM notes 
WHERE notes.provider_id = ?
 LIMIT ? OFFSET ?]
[parameters: (8, 10, 0)]
(Background on this error at: https://sqlalche.me/e/20/e3q8) - anonymous
Traceback (most recent call last):
  File "C:\Users\zelun\Desktop\Projects\Scribsy\venv\Lib\site-packages\sqlalchemy\engine\base.py", line 1963, in _exec_single_context
    self.dialect.do_execute(
  File "C:\Users\zelun\Desktop\Projects\Scribsy\venv\Lib\site-packages\sqlalchemy\engine\default.py", line 943, in do_execute
    cursor.execute(statement, parameters)
sqlite3.OperationalError: no such column: notes.s3_key

The above exception was the direct cause of the following exception:

Traceback (most recent call last):
  File "C:\Users\zelun\Desktop\Projects\Scribsy\venv\Lib\site-packages\starlette\middleware\errors.py", line 165, in __call__
    await self.app(scope, receive, _send)
  File "C:\Users\zelun\Desktop\Projects\Scribsy\venv\Lib\site-packages\starlette\middleware\cors.py", line 93, in __call__
    await self.simple_response(scope, receive, send, request_headers=headers)
  File "C:\Users\zelun\Desktop\Projects\Scribsy\venv\Lib\site-packages\starlette\middleware\cors.py", line 144, in simple_response
    await self.app(scope, receive, send)
  File "C:\Users\zelun\Desktop\Projects\Scribsy\venv\Lib\site-packages\starlette\middleware\exceptions.py", line 62, in __call__
    await wrap_app_handling_exceptions(self.app, conn)(scope, receive, send)
  File "C:\Users\zelun\Desktop\Projects\Scribsy\venv\Lib\site-packages\starlette\_exception_handler.py", line 53, in wrapped_app
    raise exc
  File "C:\Users\zelun\Desktop\Projects\Scribsy\venv\Lib\site-packages\starlette\_exception_handler.py", line 42, in wrapped_app
    await app(scope, receive, sender)
  File "C:\Users\zelun\Desktop\Projects\Scribsy\venv\Lib\site-packages\starlette\routing.py", line 714, in __call__
    await self.middleware_stack(scope, receive, send)
  File "C:\Users\zelun\Desktop\Projects\Scribsy\venv\Lib\site-packages\starlette\routing.py", line 734, in app
    await route.handle(scope, receive, send)
  File "C:\Users\zelun\Desktop\Projects\Scribsy\venv\Lib\site-packages\starlette\routing.py", line 288, in handle
    await self.app(scope, receive, send)
  File "C:\Users\zelun\Desktop\Projects\Scribsy\venv\Lib\site-packages\starlette\routing.py", line 76, in app
    await wrap_app_handling_exceptions(app, request)(scope, receive, send)
  File "C:\Users\zelun\Desktop\Projects\Scribsy\venv\Lib\site-packages\starlette\_exception_handler.py", line 53, in wrapped_app
    raise exc
  File "C:\Users\zelun\Desktop\Projects\Scribsy\venv\Lib\site-packages\starlette\_exception_handler.py", line 42, in wrapped_app
    await app(scope, receive, sender)
  File "C:\Users\zelun\Desktop\Projects\Scribsy\venv\Lib\site-packages\starlette\routing.py", line 73, in app
    response = await f(request)
               ^^^^^^^^^^^^^^^^
  File "C:\Users\zelun\AppData\Local\Programs\Python\Python311\Lib\contextlib.py", line 222, in __aexit__
    await self.gen.athrow(typ, value, traceback)
  File "C:\Users\zelun\Desktop\Projects\Scribsy\venv\Lib\site-packages\fastapi\concurrency.py", line 35, in contextmanager_in_threadpool
    raise e
  File "C:\Users\zelun\Desktop\Projects\Scribsy\venv\Lib\site-packages\fastapi\concurrency.py", line 27, in contextmanager_in_threadpool
    yield await run_in_threadpool(cm.__enter__)
  File "C:\Users\zelun\Desktop\Projects\Scribsy\venv\Lib\site-packages\fastapi\routing.py", line 301, in app
    raw_response = await run_endpoint_function(
                   ^^^^^^^^^^^^^^^^^^^^^^^^^^^^
  File "C:\Users\zelun\Desktop\Projects\Scribsy\venv\Lib\site-packages\fastapi\routing.py", line 214, in run_endpoint_function
    return await run_in_threadpool(dependant.call, **values)
           ^^^^^^^^^^^^^^^^^^^^^^^^^^^^^^^^^^^^^^^^^^^^^^^^^
  File "C:\Users\zelun\Desktop\Projects\Scribsy\venv\Lib\site-packages\starlette\concurrency.py", line 37, in run_in_threadpool
    return await anyio.to_thread.run_sync(func)
           ^^^^^^^^^^^^^^^^^^^^^^^^^^^^^^^^^^^^
  File "C:\Users\zelun\Desktop\Projects\Scribsy\venv\Lib\site-packages\anyio\to_thread.py", line 56, in run_sync
    return await get_async_backend().run_sync_in_worker_thread(
           ^^^^^^^^^^^^^^^^^^^^^^^^^^^^^^^^^^^^^^^^^^^^^^^^^^^^
  File "C:\Users\zelun\Desktop\Projects\Scribsy\venv\Lib\site-packages\anyio\_backends\_asyncio.py", line 2470, in run_sync_in_worker_thread
    return await future
           ^^^^^^^^^^^^
  File "C:\Users\zelun\Desktop\Projects\Scribsy\venv\Lib\site-packages\anyio\_backends\_asyncio.py", line 967, in run
    result = context.run(func, *args)
             ^^^^^^^^^^^^^^^^^^^^^^^^
  File "C:\Users\zelun\Desktop\Projects\Scribsy\app\api\endpoints\notes.py", line 161, in read_notes
    return crud_notes.get_notes(
           ^^^^^^^^^^^^^^^^^^^^^
  File "C:\Users\zelun\Desktop\Projects\Scribsy\app\crud\notes.py", line 88, in get_notes
    return query.offset(skip).limit(limit).all()
           ^^^^^^^^^^^^^^^^^^^^^^^^^^^^^^^^^^^^^
  File "C:\Users\zelun\Desktop\Projects\Scribsy\venv\Lib\site-packages\sqlalchemy\orm\query.py", line 2704, in all
    return self._iter().all()  # type: ignore
           ^^^^^^^^^^^^
  File "C:\Users\zelun\Desktop\Projects\Scribsy\venv\Lib\site-packages\sqlalchemy\orm\query.py", line 2857, in _iter
    result: Union[ScalarResult[_T], Result[_T]] = self.session.execute(
                                                  ^^^^^^^^^^^^^^^^^^^^^
  File "C:\Users\zelun\Desktop\Projects\Scribsy\venv\Lib\site-packages\sqlalchemy\orm\session.py", line 2365, in execute
    return self._execute_internal(
           ^^^^^^^^^^^^^^^^^^^^^^^
  File "C:\Users\zelun\Desktop\Projects\Scribsy\venv\Lib\site-packages\sqlalchemy\orm\session.py", line 2251, in _execute_internal
    result: Result[Any] = compile_state_cls.orm_execute_statement(
                          ^^^^^^^^^^^^^^^^^^^^^^^^^^^^^^^^^^^^^^^^
  File "C:\Users\zelun\Desktop\Projects\Scribsy\venv\Lib\site-packages\sqlalchemy\orm\context.py", line 306, in orm_execute_statement
    result = conn.execute(
             ^^^^^^^^^^^^^
  File "C:\Users\zelun\Desktop\Projects\Scribsy\venv\Lib\site-packages\sqlalchemy\engine\base.py", line 1415, in execute
    return meth(
           ^^^^^
  File "C:\Users\zelun\Desktop\Projects\Scribsy\venv\Lib\site-packages\sqlalchemy\sql\elements.py", line 523, in _execute_on_connection
    return connection._execute_clauseelement(
           ^^^^^^^^^^^^^^^^^^^^^^^^^^^^^^^^^^
  File "C:\Users\zelun\Desktop\Projects\Scribsy\venv\Lib\site-packages\sqlalchemy\engine\base.py", line 1637, in _execute_clauseelement
    ret = self._execute_context(
          ^^^^^^^^^^^^^^^^^^^^^^
  File "C:\Users\zelun\Desktop\Projects\Scribsy\venv\Lib\site-packages\sqlalchemy\engine\base.py", line 1842, in _execute_context
    return self._exec_single_context(
           ^^^^^^^^^^^^^^^^^^^^^^^^^^
  File "C:\Users\zelun\Desktop\Projects\Scribsy\venv\Lib\site-packages\sqlalchemy\engine\base.py", line 1982, in _exec_single_context
    self._handle_dbapi_exception(
  File "C:\Users\zelun\Desktop\Projects\Scribsy\venv\Lib\site-packages\sqlalchemy\engine\base.py", line 2351, in _handle_dbapi_exception
    raise sqlalchemy_exception.with_traceback(exc_info[2]) from e
  File "C:\Users\zelun\Desktop\Projects\Scribsy\venv\Lib\site-packages\sqlalchemy\engine\base.py", line 1963, in _exec_single_context
    self.dialect.do_execute(
  File "C:\Users\zelun\Desktop\Projects\Scribsy\venv\Lib\site-packages\sqlalchemy\engine\default.py", line 943, in do_execute
    cursor.execute(statement, parameters)
sqlalchemy.exc.OperationalError: (sqlite3.OperationalError) no such column: notes.s3_key
[SQL: SELECT notes.id AS notes_id, notes.patient_id AS notes_patient_id, notes.provider_id AS notes_provider_id, notes.visit_id AS notes_visit_id, notes.note_type AS notes_note_type, notes.content AS notes_content, notes.created_at AS notes_created_at, notes.updated_at AS notes_updated_at, notes.signed_at AS notes_signed_at, notes.status AS notes_status, notes.audio_file AS notes_audio_file, notes.s3_key AS notes_s3_key, notes.file_size AS notes_file_size, notes.content_type AS notes_content_type, notes.storage_provider AS notes_storage_provider 
FROM notes 
WHERE notes.provider_id = ?
 LIMIT ? OFFSET ?]
[parameters: (8, 10, 0)]
(Background on this error at: https://sqlalche.me/e/20/e3q8)
2025-08-19 14:23:02,262 - scribsy - ERROR - logging:68 - Error in Unhandled exception at: /notes/: (sqlite3.OperationalError) no such column: notes.s3_key
[SQL: SELECT notes.id AS notes_id, notes.patient_id AS notes_patient_id, notes.provider_id AS notes_provider_id, notes.visit_id AS notes_visit_id, notes.note_type AS notes_note_type, notes.content AS notes_content, notes.created_at AS notes_created_at, notes.updated_at AS notes_updated_at, notes.signed_at AS notes_signed_at, notes.status AS notes_status, notes.audio_file AS notes_audio_file, notes.s3_key AS notes_s3_key, notes.file_size AS notes_file_size, notes.content_type AS notes_content_type, notes.storage_provider AS notes_storage_provider 
FROM notes 
WHERE notes.provider_id = ?
 LIMIT ? OFFSET ?]
[parameters: (8, 10, 0)]
(Background on this error at: https://sqlalche.me/e/20/e3q8) - anonymous
Traceback (most recent call last):
  File "C:\Users\zelun\Desktop\Projects\Scribsy\venv\Lib\site-packages\sqlalchemy\engine\base.py", line 1963, in _exec_single_context
    self.dialect.do_execute(
  File "C:\Users\zelun\Desktop\Projects\Scribsy\venv\Lib\site-packages\sqlalchemy\engine\default.py", line 943, in do_execute
    cursor.execute(statement, parameters)
sqlite3.OperationalError: no such column: notes.s3_key

The above exception was the direct cause of the following exception:

Traceback (most recent call last):
  File "C:\Users\zelun\Desktop\Projects\Scribsy\venv\Lib\site-packages\starlette\middleware\errors.py", line 165, in __call__
    await self.app(scope, receive, _send)
  File "C:\Users\zelun\Desktop\Projects\Scribsy\venv\Lib\site-packages\starlette\middleware\cors.py", line 93, in __call__
    await self.simple_response(scope, receive, send, request_headers=headers)
  File "C:\Users\zelun\Desktop\Projects\Scribsy\venv\Lib\site-packages\starlette\middleware\cors.py", line 144, in simple_response
    await self.app(scope, receive, send)
  File "C:\Users\zelun\Desktop\Projects\Scribsy\venv\Lib\site-packages\starlette\middleware\exceptions.py", line 62, in __call__
    await wrap_app_handling_exceptions(self.app, conn)(scope, receive, send)
  File "C:\Users\zelun\Desktop\Projects\Scribsy\venv\Lib\site-packages\starlette\_exception_handler.py", line 53, in wrapped_app
    raise exc
  File "C:\Users\zelun\Desktop\Projects\Scribsy\venv\Lib\site-packages\starlette\_exception_handler.py", line 42, in wrapped_app
    await app(scope, receive, sender)
  File "C:\Users\zelun\Desktop\Projects\Scribsy\venv\Lib\site-packages\starlette\routing.py", line 714, in __call__
    await self.middleware_stack(scope, receive, send)
  File "C:\Users\zelun\Desktop\Projects\Scribsy\venv\Lib\site-packages\starlette\routing.py", line 734, in app
    await route.handle(scope, receive, send)
  File "C:\Users\zelun\Desktop\Projects\Scribsy\venv\Lib\site-packages\starlette\routing.py", line 288, in handle
    await self.app(scope, receive, send)
  File "C:\Users\zelun\Desktop\Projects\Scribsy\venv\Lib\site-packages\starlette\routing.py", line 76, in app
    await wrap_app_handling_exceptions(app, request)(scope, receive, send)
  File "C:\Users\zelun\Desktop\Projects\Scribsy\venv\Lib\site-packages\starlette\_exception_handler.py", line 53, in wrapped_app
    raise exc
  File "C:\Users\zelun\Desktop\Projects\Scribsy\venv\Lib\site-packages\starlette\_exception_handler.py", line 42, in wrapped_app
    await app(scope, receive, sender)
  File "C:\Users\zelun\Desktop\Projects\Scribsy\venv\Lib\site-packages\starlette\routing.py", line 73, in app
    response = await f(request)
               ^^^^^^^^^^^^^^^^
  File "C:\Users\zelun\AppData\Local\Programs\Python\Python311\Lib\contextlib.py", line 222, in __aexit__
    await self.gen.athrow(typ, value, traceback)
  File "C:\Users\zelun\Desktop\Projects\Scribsy\venv\Lib\site-packages\fastapi\concurrency.py", line 35, in contextmanager_in_threadpool
    raise e
  File "C:\Users\zelun\Desktop\Projects\Scribsy\venv\Lib\site-packages\fastapi\concurrency.py", line 27, in contextmanager_in_threadpool
    yield await run_in_threadpool(cm.__enter__)
  File "C:\Users\zelun\Desktop\Projects\Scribsy\venv\Lib\site-packages\fastapi\routing.py", line 301, in app
    raw_response = await run_endpoint_function(
                   ^^^^^^^^^^^^^^^^^^^^^^^^^^^^
  File "C:\Users\zelun\Desktop\Projects\Scribsy\venv\Lib\site-packages\fastapi\routing.py", line 214, in run_endpoint_function
    return await run_in_threadpool(dependant.call, **values)
           ^^^^^^^^^^^^^^^^^^^^^^^^^^^^^^^^^^^^^^^^^^^^^^^^^
  File "C:\Users\zelun\Desktop\Projects\Scribsy\venv\Lib\site-packages\starlette\concurrency.py", line 37, in run_in_threadpool
    return await anyio.to_thread.run_sync(func)
           ^^^^^^^^^^^^^^^^^^^^^^^^^^^^^^^^^^^^
  File "C:\Users\zelun\Desktop\Projects\Scribsy\venv\Lib\site-packages\anyio\to_thread.py", line 56, in run_sync
    return await get_async_backend().run_sync_in_worker_thread(
           ^^^^^^^^^^^^^^^^^^^^^^^^^^^^^^^^^^^^^^^^^^^^^^^^^^^^
  File "C:\Users\zelun\Desktop\Projects\Scribsy\venv\Lib\site-packages\anyio\_backends\_asyncio.py", line 2470, in run_sync_in_worker_thread
    return await future
           ^^^^^^^^^^^^
  File "C:\Users\zelun\Desktop\Projects\Scribsy\venv\Lib\site-packages\anyio\_backends\_asyncio.py", line 967, in run
    result = context.run(func, *args)
             ^^^^^^^^^^^^^^^^^^^^^^^^
  File "C:\Users\zelun\Desktop\Projects\Scribsy\app\api\endpoints\notes.py", line 161, in read_notes
    return crud_notes.get_notes(
           ^^^^^^^^^^^^^^^^^^^^^
  File "C:\Users\zelun\Desktop\Projects\Scribsy\app\crud\notes.py", line 88, in get_notes
    return query.offset(skip).limit(limit).all()
           ^^^^^^^^^^^^^^^^^^^^^^^^^^^^^^^^^^^^^
  File "C:\Users\zelun\Desktop\Projects\Scribsy\venv\Lib\site-packages\sqlalchemy\orm\query.py", line 2704, in all
    return self._iter().all()  # type: ignore
           ^^^^^^^^^^^^
  File "C:\Users\zelun\Desktop\Projects\Scribsy\venv\Lib\site-packages\sqlalchemy\orm\query.py", line 2857, in _iter
    result: Union[ScalarResult[_T], Result[_T]] = self.session.execute(
                                                  ^^^^^^^^^^^^^^^^^^^^^
  File "C:\Users\zelun\Desktop\Projects\Scribsy\venv\Lib\site-packages\sqlalchemy\orm\session.py", line 2365, in execute
    return self._execute_internal(
           ^^^^^^^^^^^^^^^^^^^^^^^
  File "C:\Users\zelun\Desktop\Projects\Scribsy\venv\Lib\site-packages\sqlalchemy\orm\session.py", line 2251, in _execute_internal
    result: Result[Any] = compile_state_cls.orm_execute_statement(
                          ^^^^^^^^^^^^^^^^^^^^^^^^^^^^^^^^^^^^^^^^
  File "C:\Users\zelun\Desktop\Projects\Scribsy\venv\Lib\site-packages\sqlalchemy\orm\context.py", line 306, in orm_execute_statement
    result = conn.execute(
             ^^^^^^^^^^^^^
  File "C:\Users\zelun\Desktop\Projects\Scribsy\venv\Lib\site-packages\sqlalchemy\engine\base.py", line 1415, in execute
    return meth(
           ^^^^^
  File "C:\Users\zelun\Desktop\Projects\Scribsy\venv\Lib\site-packages\sqlalchemy\sql\elements.py", line 523, in _execute_on_connection
    return connection._execute_clauseelement(
           ^^^^^^^^^^^^^^^^^^^^^^^^^^^^^^^^^^
  File "C:\Users\zelun\Desktop\Projects\Scribsy\venv\Lib\site-packages\sqlalchemy\engine\base.py", line 1637, in _execute_clauseelement
    ret = self._execute_context(
          ^^^^^^^^^^^^^^^^^^^^^^
  File "C:\Users\zelun\Desktop\Projects\Scribsy\venv\Lib\site-packages\sqlalchemy\engine\base.py", line 1842, in _execute_context
    return self._exec_single_context(
           ^^^^^^^^^^^^^^^^^^^^^^^^^^
  File "C:\Users\zelun\Desktop\Projects\Scribsy\venv\Lib\site-packages\sqlalchemy\engine\base.py", line 1982, in _exec_single_context
    self._handle_dbapi_exception(
  File "C:\Users\zelun\Desktop\Projects\Scribsy\venv\Lib\site-packages\sqlalchemy\engine\base.py", line 2351, in _handle_dbapi_exception
    raise sqlalchemy_exception.with_traceback(exc_info[2]) from e
  File "C:\Users\zelun\Desktop\Projects\Scribsy\venv\Lib\site-packages\sqlalchemy\engine\base.py", line 1963, in _exec_single_context
    self.dialect.do_execute(
  File "C:\Users\zelun\Desktop\Projects\Scribsy\venv\Lib\site-packages\sqlalchemy\engine\default.py", line 943, in do_execute
    cursor.execute(statement, parameters)
sqlalchemy.exc.OperationalError: (sqlite3.OperationalError) no such column: notes.s3_key
[SQL: SELECT notes.id AS notes_id, notes.patient_id AS notes_patient_id, notes.provider_id AS notes_provider_id, notes.visit_id AS notes_visit_id, notes.note_type AS notes_note_type, notes.content AS notes_content, notes.created_at AS notes_created_at, notes.updated_at AS notes_updated_at, notes.signed_at AS notes_signed_at, notes.status AS notes_status, notes.audio_file AS notes_audio_file, notes.s3_key AS notes_s3_key, notes.file_size AS notes_file_size, notes.content_type AS notes_content_type, notes.storage_provider AS notes_storage_provider 
FROM notes 
WHERE notes.provider_id = ?
 LIMIT ? OFFSET ?]
[parameters: (8, 10, 0)]
(Background on this error at: https://sqlalche.me/e/20/e3q8)
2025-08-19 14:23:02,276 - scribsy - ERROR - logging:68 - Error in Unhandled exception at: /notes/: (sqlite3.OperationalError) no such column: notes.s3_key
[SQL: SELECT notes.id AS notes_id, notes.patient_id AS notes_patient_id, notes.provider_id AS notes_provider_id, notes.visit_id AS notes_visit_id, notes.note_type AS notes_note_type, notes.content AS notes_content, notes.created_at AS notes_created_at, notes.updated_at AS notes_updated_at, notes.signed_at AS notes_signed_at, notes.status AS notes_status, notes.audio_file AS notes_audio_file, notes.s3_key AS notes_s3_key, notes.file_size AS notes_file_size, notes.content_type AS notes_content_type, notes.storage_provider AS notes_storage_provider 
FROM notes 
WHERE notes.provider_id = ?
 LIMIT ? OFFSET ?]
[parameters: (8, 10, 0)]
(Background on this error at: https://sqlalche.me/e/20/e3q8) - anonymous
Traceback (most recent call last):
  File "C:\Users\zelun\Desktop\Projects\Scribsy\venv\Lib\site-packages\sqlalchemy\engine\base.py", line 1963, in _exec_single_context
    self.dialect.do_execute(
  File "C:\Users\zelun\Desktop\Projects\Scribsy\venv\Lib\site-packages\sqlalchemy\engine\default.py", line 943, in do_execute
    cursor.execute(statement, parameters)
sqlite3.OperationalError: no such column: notes.s3_key

The above exception was the direct cause of the following exception:

Traceback (most recent call last):
  File "C:\Users\zelun\Desktop\Projects\Scribsy\venv\Lib\site-packages\starlette\middleware\errors.py", line 165, in __call__
    await self.app(scope, receive, _send)
  File "C:\Users\zelun\Desktop\Projects\Scribsy\venv\Lib\site-packages\starlette\middleware\cors.py", line 93, in __call__
    await self.simple_response(scope, receive, send, request_headers=headers)
  File "C:\Users\zelun\Desktop\Projects\Scribsy\venv\Lib\site-packages\starlette\middleware\cors.py", line 144, in simple_response
    await self.app(scope, receive, send)
  File "C:\Users\zelun\Desktop\Projects\Scribsy\venv\Lib\site-packages\starlette\middleware\exceptions.py", line 62, in __call__
    await wrap_app_handling_exceptions(self.app, conn)(scope, receive, send)
  File "C:\Users\zelun\Desktop\Projects\Scribsy\venv\Lib\site-packages\starlette\_exception_handler.py", line 53, in wrapped_app
    raise exc
  File "C:\Users\zelun\Desktop\Projects\Scribsy\venv\Lib\site-packages\starlette\_exception_handler.py", line 42, in wrapped_app
    await app(scope, receive, sender)
  File "C:\Users\zelun\Desktop\Projects\Scribsy\venv\Lib\site-packages\starlette\routing.py", line 714, in __call__
    await self.middleware_stack(scope, receive, send)
  File "C:\Users\zelun\Desktop\Projects\Scribsy\venv\Lib\site-packages\starlette\routing.py", line 734, in app
    await route.handle(scope, receive, send)
  File "C:\Users\zelun\Desktop\Projects\Scribsy\venv\Lib\site-packages\starlette\routing.py", line 288, in handle
    await self.app(scope, receive, send)
  File "C:\Users\zelun\Desktop\Projects\Scribsy\venv\Lib\site-packages\starlette\routing.py", line 76, in app
    await wrap_app_handling_exceptions(app, request)(scope, receive, send)
  File "C:\Users\zelun\Desktop\Projects\Scribsy\venv\Lib\site-packages\starlette\_exception_handler.py", line 53, in wrapped_app
    raise exc
  File "C:\Users\zelun\Desktop\Projects\Scribsy\venv\Lib\site-packages\starlette\_exception_handler.py", line 42, in wrapped_app
    await app(scope, receive, sender)
  File "C:\Users\zelun\Desktop\Projects\Scribsy\venv\Lib\site-packages\starlette\routing.py", line 73, in app
    response = await f(request)
               ^^^^^^^^^^^^^^^^
  File "C:\Users\zelun\AppData\Local\Programs\Python\Python311\Lib\contextlib.py", line 222, in __aexit__
    await self.gen.athrow(typ, value, traceback)
  File "C:\Users\zelun\Desktop\Projects\Scribsy\venv\Lib\site-packages\fastapi\concurrency.py", line 35, in contextmanager_in_threadpool
    raise e
  File "C:\Users\zelun\Desktop\Projects\Scribsy\venv\Lib\site-packages\fastapi\concurrency.py", line 27, in contextmanager_in_threadpool
    yield await run_in_threadpool(cm.__enter__)
  File "C:\Users\zelun\Desktop\Projects\Scribsy\venv\Lib\site-packages\fastapi\routing.py", line 301, in app
    raw_response = await run_endpoint_function(
                   ^^^^^^^^^^^^^^^^^^^^^^^^^^^^
  File "C:\Users\zelun\Desktop\Projects\Scribsy\venv\Lib\site-packages\fastapi\routing.py", line 214, in run_endpoint_function
    return await run_in_threadpool(dependant.call, **values)
           ^^^^^^^^^^^^^^^^^^^^^^^^^^^^^^^^^^^^^^^^^^^^^^^^^
  File "C:\Users\zelun\Desktop\Projects\Scribsy\venv\Lib\site-packages\starlette\concurrency.py", line 37, in run_in_threadpool
    return await anyio.to_thread.run_sync(func)
           ^^^^^^^^^^^^^^^^^^^^^^^^^^^^^^^^^^^^
  File "C:\Users\zelun\Desktop\Projects\Scribsy\venv\Lib\site-packages\anyio\to_thread.py", line 56, in run_sync
    return await get_async_backend().run_sync_in_worker_thread(
           ^^^^^^^^^^^^^^^^^^^^^^^^^^^^^^^^^^^^^^^^^^^^^^^^^^^^
  File "C:\Users\zelun\Desktop\Projects\Scribsy\venv\Lib\site-packages\anyio\_backends\_asyncio.py", line 2470, in run_sync_in_worker_thread
    return await future
           ^^^^^^^^^^^^
  File "C:\Users\zelun\Desktop\Projects\Scribsy\venv\Lib\site-packages\anyio\_backends\_asyncio.py", line 967, in run
    result = context.run(func, *args)
             ^^^^^^^^^^^^^^^^^^^^^^^^
  File "C:\Users\zelun\Desktop\Projects\Scribsy\app\api\endpoints\notes.py", line 161, in read_notes
    return crud_notes.get_notes(
           ^^^^^^^^^^^^^^^^^^^^^
  File "C:\Users\zelun\Desktop\Projects\Scribsy\app\crud\notes.py", line 88, in get_notes
    return query.offset(skip).limit(limit).all()
           ^^^^^^^^^^^^^^^^^^^^^^^^^^^^^^^^^^^^^
  File "C:\Users\zelun\Desktop\Projects\Scribsy\venv\Lib\site-packages\sqlalchemy\orm\query.py", line 2704, in all
    return self._iter().all()  # type: ignore
           ^^^^^^^^^^^^
  File "C:\Users\zelun\Desktop\Projects\Scribsy\venv\Lib\site-packages\sqlalchemy\orm\query.py", line 2857, in _iter
    result: Union[ScalarResult[_T], Result[_T]] = self.session.execute(
                                                  ^^^^^^^^^^^^^^^^^^^^^
  File "C:\Users\zelun\Desktop\Projects\Scribsy\venv\Lib\site-packages\sqlalchemy\orm\session.py", line 2365, in execute
    return self._execute_internal(
           ^^^^^^^^^^^^^^^^^^^^^^^
  File "C:\Users\zelun\Desktop\Projects\Scribsy\venv\Lib\site-packages\sqlalchemy\orm\session.py", line 2251, in _execute_internal
    result: Result[Any] = compile_state_cls.orm_execute_statement(
                          ^^^^^^^^^^^^^^^^^^^^^^^^^^^^^^^^^^^^^^^^
  File "C:\Users\zelun\Desktop\Projects\Scribsy\venv\Lib\site-packages\sqlalchemy\orm\context.py", line 306, in orm_execute_statement
    result = conn.execute(
             ^^^^^^^^^^^^^
  File "C:\Users\zelun\Desktop\Projects\Scribsy\venv\Lib\site-packages\sqlalchemy\engine\base.py", line 1415, in execute
    return meth(
           ^^^^^
  File "C:\Users\zelun\Desktop\Projects\Scribsy\venv\Lib\site-packages\sqlalchemy\sql\elements.py", line 523, in _execute_on_connection
    return connection._execute_clauseelement(
           ^^^^^^^^^^^^^^^^^^^^^^^^^^^^^^^^^^
  File "C:\Users\zelun\Desktop\Projects\Scribsy\venv\Lib\site-packages\sqlalchemy\engine\base.py", line 1637, in _execute_clauseelement
    ret = self._execute_context(
          ^^^^^^^^^^^^^^^^^^^^^^
  File "C:\Users\zelun\Desktop\Projects\Scribsy\venv\Lib\site-packages\sqlalchemy\engine\base.py", line 1842, in _execute_context
    return self._exec_single_context(
           ^^^^^^^^^^^^^^^^^^^^^^^^^^
  File "C:\Users\zelun\Desktop\Projects\Scribsy\venv\Lib\site-packages\sqlalchemy\engine\base.py", line 1982, in _exec_single_context
    self._handle_dbapi_exception(
  File "C:\Users\zelun\Desktop\Projects\Scribsy\venv\Lib\site-packages\sqlalchemy\engine\base.py", line 2351, in _handle_dbapi_exception
    raise sqlalchemy_exception.with_traceback(exc_info[2]) from e
  File "C:\Users\zelun\Desktop\Projects\Scribsy\venv\Lib\site-packages\sqlalchemy\engine\base.py", line 1963, in _exec_single_context
    self.dialect.do_execute(
  File "C:\Users\zelun\Desktop\Projects\Scribsy\venv\Lib\site-packages\sqlalchemy\engine\default.py", line 943, in do_execute
    cursor.execute(statement, parameters)
sqlalchemy.exc.OperationalError: (sqlite3.OperationalError) no such column: notes.s3_key
[SQL: SELECT notes.id AS notes_id, notes.patient_id AS notes_patient_id, notes.provider_id AS notes_provider_id, notes.visit_id AS notes_visit_id, notes.note_type AS notes_note_type, notes.content AS notes_content, notes.created_at AS notes_created_at, notes.updated_at AS notes_updated_at, notes.signed_at AS notes_signed_at, notes.status AS notes_status, notes.audio_file AS notes_audio_file, notes.s3_key AS notes_s3_key, notes.file_size AS notes_file_size, notes.content_type AS notes_content_type, notes.storage_provider AS notes_storage_provider 
FROM notes 
WHERE notes.provider_id = ?
 LIMIT ? OFFSET ?]
[parameters: (8, 10, 0)]
(Background on this error at: https://sqlalche.me/e/20/e3q8)
